Workbook
Name \0: #REF!
Name \a: #REF!
Name \b: #REF!
Name \c: #REF!
Name \d: #REF!
Name \df: #N/A
Name \e: #REF!
Name \f: #REF!
Name \i: #REF!
Name \l: #REF!
Name \PRINT_BALANCO: #REF!
Name \r: #REF!
Name \s: #REF!
Name \t: #REF!
Name _________________________________INV12: #REF!
Name _________________________________INV13: #REF!
Name _________________________________inv2: #REF!
Name _________________________________inv2: #REF!
Name _________________________________inv2: #REF!
Name ________________________________INV12: #REF!
Name ________________________________INV13: #REF!
Name ________________________________inv2: #REF!
Name ________________________________inv2: #REF!
Name ________________________________inv2: #REF!
Name _______________________________INV12: #REF!
Name _______________________________INV13: #REF!
Name _______________________________inv2: #REF!
Name _______________________________inv2: #REF!
Name _______________________________inv2: #REF!
Name ______________________________INV12: #REF!
Name ______________________________INV13: #REF!
Name ______________________________inv2: #REF!
Name ______________________________inv2: #REF!
Name ______________________________inv2: #REF!
Name _____________________________INV12: #REF!
Name _____________________________INV13: #REF!
Name _____________________________inv2: #REF!
Name _____________________________inv2: #REF!
Name _____________________________inv2: #REF!
Name ____________________________INV12: #REF!
Name ____________________________INV13: #REF!
Name ____________________________inv2: #REF!
Name ____________________________inv2: #REF!
Name ____________________________inv2: #REF!
Name ___________________________INV12: #REF!
Name ___________________________INV13: #REF!
Name ___________________________inv2: #REF!
Name ___________________________inv2: #REF!
Name ___________________________inv2: #REF!
Name __________________________INV12: #REF!
Name __________________________INV13: #REF!
Name __________________________inv2: #REF!
Name __________________________inv2: #REF!
Name __________________________inv2: #REF!
Name _________________________INV12: #REF!
Name _________________________INV13: #REF!
Name _________________________inv2: #REF!
Name _________________________inv2: #REF!
Name _________________________inv2: #REF!
Name ________________________INV12: #REF!

Sheet Meta (2)
A1: META 2026 | C1: YTD | G1: jan a jun | H1: jan a ago | I1: projeção ate dez
A2: Meta Anual | B2: 12 | C2: 1 | D2: 11 | E2: Nova meta mês | G2: 3120555 | H2: =C3 -> 444545.69 | I2: =H2+576522+85120+420000+374267+140000+(400000*3) -> 3240454.7 | K2: 576622 | L2: Nacionais
A3: 8060000 | B3: =A3/B2 -> 671666.67 | C3: ='Areas Sintetico atualizado'!C3 -> 444545.69 | D3: =A3-C3 -> 7615454.3 | E3: =D3/D2 -> 692314.03 | G3: =G2/A3 -> 0.38716563 | H3: =H2/A3 -> 0.055154552 | I3: =I2/A3 -> 0.40204152 | K3: 85120 | L3: Internacionais
K4: 420000 | L4: Pre faturas
H5: =10377407-5768380 -> 4609027 | K5: 374267 | L5: WM
H6: =(H2/H5)-1 -> -0.90354891 | K6: 140000 | L6: Tonico
A7: META 2025 | C7: YTD | I7: 6143091
A8: Meta Anual | B8: 12 | I8: =(I2/I7)-1 -> -0.4725042
A9: =A3 -> 8060000 | B9: =A9/B8 -> 671666.67 | C9: ='Areas Sintetico atualizado'!L3 -> 444545.69 | E9: =A9-C9 -> 7615454.3 | F9: =E9/D2 -> 692314.03
B13: Recebimento | C13: Faturamento | D13: Meta | E13: Despesas | F13: Despesas indiretas | G13: Custo direto
A14: Jan | B14: ='Areas Sintetico atualizado'!C4 -> 279821.07 | C14: ='Areas Sintetico atualizado'!C3 -> 444545.69 | D14: 671667 | E14: =F14+G14 -> 316604.06 | F14: ='Areas Sintetico atualizado'!C13 -> 104973.54 | G14: ='Areas Sintetico atualizado'!C6 -> 211630.52 | I14: =B14-F14-G14 -> -36782.99
A15: Fev | D15: 671667 | E15: =F15+G15 -> 0 | I15: =B15-F15-G15 -> 0
A16: Mar | D16: 671667 | E16: =F16+G16 -> 0 | I16: =B16-F16-G16 -> 0
A17: Abr | D17: 671667 | E17: =F17+G17 -> 0 | I17: =B17-F17-G17 -> 0
A18: Mai | D18: 671667 | E18: =F18+G18 -> 0 | I18: =B18-F18-G18 -> 0
A19: Jun | D19: 671667 | E19: =F19+G19 -> 0 | I19: =B19-F19-G19 -> 0
A20: Jul | D20: 671667 | E20: =F20+G20 -> 0 | I20: =B20-F20-G20 -> 0
A21: Ago | D21: 671667 | E21: =F21+G21 -> 0 | I21: =B21-F21-G21 -> 0
A22: Set | D22: 671667 | E22: =F22+G22 -> 0 | I22: =B22-F22-G22 -> 0
A23: Out | D23: 671667 | E23: =F23+G23 -> 0 | I23: =B23-F23-G23 -> 0
A24: Nov | D24: 671667 | E24: =F24+G24 -> 0 | I24: =B24-F24-G24 -> 0
A25: Dez | D25: 671667 | E25: =F25+G25 -> 0 | I25: =B25-F25-G25 -> 0
B26: =SUM(B14:B25) -> 279821.07 | C26: =SUM(C14:C25) -> 444545.69 | D26: =SUM(D14:D25) -> 8060004 | E26: =SUM(E14:E25) -> 316604.06 | F26: =SUM(F14:F25) -> 104973.54 | G26: =SUM(G14:G25) -> 211630.52 | H26: =SUM(H14:H25) -> 0 | I26: =SUM(I14:I25) -> -36782.99
A28: MÉDIA ANUAL | B28: =B26/12 -> 23318.423
D31: =C26-F26-G26 -> 127941.63 | E31: =B26-F26-G26 -> -36782.99
B35: Recebimento | C35: Despesas | E35: #
A36: Jan | B36: 316807.42 | C36: 330244.38 | D36: ='[1]Base_Resultado Mensal_V2'!D190 -> 134911.6 | E36: =B36-C36-D36 -> -148348.56
A37: Fev | B37: 216057.27 | C37: 377306.7 | D37: ='[1]Base_Resultado Mensal_V2'!F190 -> 5092.45 | E37: =B37-C37-D37 -> -166341.88
A38: Mar | B38: 613202.96 | C38: 363984.21 | D38: ='[1]Base_Resultado Mensal_V2'!H190 -> 814.99 | E38: =B38-C38-D38 -> 248403.76
A39: Abr | B39: 588260.32 | C39: 375072.46 | D39: ='[1]Base_Resultado Mensal_V2'!J190 -> 110831.76 | E39: =B39-C39-D39 -> 102356.1
A40: Mai | B40: 658171.05 | C40: 360112.8 | D40: ='[1]Base_Resultado Mensal_V2'!L190 -> 5968 | E40: =B40-C40-D40 -> 292090.25
A41: Jun | B41: 632809.49 | C41: 334821.86 | D41: ='[1]Base_Resultado Mensal_V2'!N190 -> 11928.17 | E41: =B41-C41-D41 -> 286059.46
A42: Jul | B42: 260036.93 | C42: 337422.56 | D42: ='[1]Base_Resultado Mensal_V2'!P190 -> 183171.96 | E42: =B42-C42-D42 -> -260557.59
B43: 3285345.4 | C43: 2478965 | D43: =SUM(D36:D42) -> 452718.93

Sheet Rateio Mensal
A1: JANEIRO | E1: Orçado | H1: DESPESAS RATEADAS | K1: Rateio anual
A2: =K2 -> Custo equipe - Contencioso | B2: ='Base_Resultado Mensal_V2'!C5 -> 73576.315 | C2: =+B2/B5 -> 0.34766401 | E2: ='Areas Sintetico atualizado'!B39 -> 74354.065 | F2: =E2/$E$5 -> 0.34839708 | H2: =('Base_Resultado Mensal_V2'!C194)-'Base_Resultado Mensal_V2'!C200-'Base_Resultado Mensal_V2'!C201-'Base_Resultado Mensal_V2'!C202 -> 101895.64 | I2: =$H$2*C2 -> 35425.447 | K2: ='DRE 2026'!A6 -> Custo equipe - Contencioso | L2: ='DRE 2026'!B6 -> 881797.73 | M2: =L2/$L$5 -> 0.36682229
A3: =K3 -> Custo equipe - Econômico | B3: ='Base_Resultado Mensal_V2'!C30 -> 76041.035 | C3: =+B3/B5 -> 0.35931034 | E3: ='Areas Sintetico atualizado'!B57 -> 76879.165 | F3: =E3/$E$5 -> 0.36022881 | I3: =$H$2*C3 -> 36612.157 | K3: ='DRE 2026'!A7 -> Custo equipe - Econômico | L3: ='DRE 2026'!B7 -> 914114.75 | M3: =L3/$L$5 -> 0.38026596
A4: =K4 -> Custo equipe - Arbitragem e Compliance | B4: ='Base_Resultado Mensal_V2'!C58 -> 62013.17 | C4: =B4/$B$5 -> 0.29302565 | E4: ='Areas Sintetico atualizado'!B75 -> 62184.36 | F4: =E4/$E$5 -> 0.29137411 | I4: =$H$2*C4 -> 29858.036 | K4: ='DRE 2026'!A8 -> Custo equipe - Arbitragem e Compliance | L4: ='DRE 2026'!B8 -> 607970.16 | M4: =L4/$L$5 -> 0.25291175
A5: Total das Áreas | B5: =SUM(B2:B4) -> 211630.52 | C5: =SUM(C2:C4) -> 1 | E5: =SUM(E2:E4) -> 213417.59 | K5: =A5 -> Total das Áreas | L5: =SUM(L2:L4) -> 2403882.6 | M5: =SUM(M2:M4) -> 1
A7: FEVEREIRO
A8: =K2 -> Custo equipe - Contencioso | B8: ='Base_Resultado Mensal_V2'!D5 -> 76342.345 | C8: =+B8/B11 -> 0.34953137 | E8: ='DRE 2026'!D6 -> 72754.065 | F8: =E8/$E$11 -> 0.34857659 | H8: ='Base_Resultado Mensal_V2'!D203 -> 90395.7 | I8: =$H$8*C8 -> 31596.133
A9: =K3 -> Custo equipe - Econômico | B9: ='Base_Resultado Mensal_V2'!D30 -> 80276.745 | C9: =+B9/B11 -> 0.36754491 | E9: ='DRE 2026'!D7 -> 75379.165 | F9: =E9/$E$11 -> 0.36115387 | I9: =$H$8*C9 -> 33224.48
A10: =K4 -> Custo equipe - Arbitragem e Compliance | B10: ='Base_Resultado Mensal_V2'!D58 -> 61794.34 | C10: =B10/$B$11 -> 0.28292372 | E10: ='DRE 2026'!D8 -> 60584.36 | F10: =E10/$E$11 -> 0.29026955 | I10: =$H$8*C10 -> 25575.088
A11: =K5 -> Total das Áreas | B11: =SUM(B8:B10) -> 218413.43 | C11: =SUM(C8:C10) -> 1 | E11: =SUM(E8:E10) -> 208717.59

Sheet Fluxo consolidado 
B1: 671666.67
B2: Janeiro | C2: Fevereiro | D2: Março | E2: Abril | F2: Maio | G2: Junho | H2: Julho | I2: Agosto | J2: Setembro | K2: Outubro | L2: Novembro | M2: Dezembro | N2: 1
A3: Contencioso | B3: Realizado | C3: Realizado | D3: Realizado | E3: Realizado | F3: Realizado | G3: Realizado | H3: Realizado | I3: Realizado | J3: Realizado | K3: Realizado | L3: Realizado | M3: Realizado | N3: TOTAL
A4: Recebimento | B4: ='Areas Sintetico atualizado'!C36 -> 72613.091 | N4: =B4+C4+D4+E4+F4+G4+H4+I4+J4+K4+L4+M4 -> 72613.091 | P4: Minimo de receita
A5: Equipe | B5: ='Areas Sintetico atualizado'!C39+'Areas Sintetico atualizado'!C40 -> 73576.315 | N5: =B5+C5+D5+E5+F5+G5+H5+I5+J5+K5+L5+M5 -> 73576.315 | P5: =(N5+N6+N7+N8)/$N$2 -> 123775.81
A6: Despesas | B6: ='Areas Sintetico atualizado'!C41+'Areas Sintetico atualizado'!C42 -> 36485.542 | N6: =B6+C6+D6+E6+F6+G6+H6+I6+J6+K6+L6+M6 -> 36485.542
A7: Impostos | B7: ='Areas Sintetico atualizado'!C46 -> 10891.964 | N7: =B7+C7+D7+E7+F7+G7+H7+I7+J7+K7+L7+M7 -> 10891.964 | P7: Margem Liq.
A8: Investimento amortizaçao | B8: ='Areas Sintetico atualizado'!C47 -> 2821.9888 | N8: =B8+C8+D8+E8+F8+G8+H8+I8+J8+K8+L8+M8 -> 2821.9888
A9: Margem liquida | B9: =B4-B5-B6-B7-B8 -> -51162.718 | C9: =C4-C5-C6-C7-C8 -> 0 | D9: =D4-D5-D6-D7-D8 -> 0 | E9: =E4-E5-E6-E7-E8 -> 0 | F9: =F4-F5-F6-F7-F8 -> 0 | G9: =G4-G5-G6-G7-G8 -> 0 | H9: =H4-H5-H6-H7-H8 -> 0 | I9: =I4-I5-I6-I7-I8 -> 0 | ... N9: =N4-N5-N6-N7-N8 -> -51162.718 | P9: =N9/N4 -> -0.70459359
B11: Janeiro | C11: Fevereiro | D11: Março | E11: Abril | F11: Maio | G11: Junho | H11: Julho | I11: Agosto | J11: Setembro | K11: =K2 -> Outubro | L11: =L2 -> Novembro | M11: =M2 -> Dezembro
A12: Economico | B12: Realizado | C12: Realizado | D12: Realizado | E12: Realizado | F12: Realizado | G12: Realizado | H12: Realizado | I12: Realizado | J12: Realizado | K12: Realizado | L12: Realizado | M12: Realizado | N12: TOTAL
A13: Recebimento | B13: ='Areas Sintetico atualizado'!C54 -> 120362.57 | N13: =B13+C13+D13+E13+F13+G13+H13+I13+J13+K13+L13+M13 -> 120362.57 | P13: Minimo de receita
A14: Equipe | B14: ='Areas Sintetico atualizado'!C57 -> 76041.035 | N14: =B14+C14+D14+E14+F14+G14+H14+I14+J14+K14+L14+M14 -> 76041.035 | P14: =(N14+N15+N16+N17)/$N$2 -> 135495.91
A15: Despesas | B15: ='Areas Sintetico atualizado'!C59+'Areas Sintetico atualizado'!C60 -> 38483.962 | N15: =B15+C15+D15+E15+F15+G15+H15+I15+J15+K15+L15+M15 -> 38483.962
A16: Impostos | B16: ='Areas Sintetico atualizado'!C64 -> 18054.386 | N16: =B16+C16+D16+E16+F16+G16+H16+I16+J16+K16+L16+M16 -> 18054.386 | P16: Margem Liq.
A17: Investimento amortizaçao | B17: ='Areas Sintetico atualizado'!C65 -> 2916.5221 | N17: =B17+C17+D17+E17+F17+G17+H17+I17+J17+K17+L17+M17 -> 2916.5221
A18: Margem liquida | B18: =B13-B14-B15-B16-B17 -> -15133.331 | C18: =C13-C14-C15-C16-C17 -> 0 | D18: =D13-D14-D15-D16-D17 -> 0 | E18: =E13-E14-E15-E16-E17 -> 0 | F18: =F13-F14-F15-F16-F17 -> 0 | G18: =G13-G14-G15-G16-G17 -> 0 | H18: =H13-H14-H15-H16-H17 -> 0 | I18: =I13-I14-I15-I16-I17 -> 0 | ... N18: =N13-N14-N15-N16-N17 -> -15133.331 | P18: =N18/N13 -> -0.1257312
B20: Janeiro | C20: Fevereiro | D20: Março | E20: Abril | F20: Maio | G20: Junho | H20: Julho | I20: Agosto | J20: Setembro | K20: =K2 -> Outubro | L20: =L2 -> Novembro | M20: =M2 -> Dezembro
A21: Arbitragem | B21: Realizado | C21: Realizado | D21: Realizado | E21: Realizado | F21: Realizado | G21: Realizado | H21: Realizado | I21: Realizado | J21: Realizado | K21: Realizado | L21: Realizado | M21: Realizado | N21: TOTAL
A22: Recebimento | B22: ='Areas Sintetico atualizado'!C72 -> 86846.335 | N22: =B22+C22+D22+E22+F22+G22+H22+I22+J22+K22+L22+M22 -> 86846.335 | P22: Minimo de receita
A23: Equipe | B23: ='Areas Sintetico atualizado'!C75 -> 62013.17 | N23: =B23+C23+D23+E23+F23+G23+H23+I23+J23+K23+L23+M23 -> 62013.17 | P23: =(N23+N24+N25+N26)/$N$2 -> 107422.65
A24: Despesas | B24: ='Areas Sintetico atualizado'!C77+'Areas Sintetico atualizado'!C78 -> 30004.036 | N24: =B24+C24+D24+E24+F24+G24+H24+I24+J24+K24+L24+M24 -> 30004.036
A25: Impostos | B25: ='Areas Sintetico atualizado'!C82 -> 13026.95 | N25: =B25+C25+D25+E25+F25+G25+H25+I25+J25+K25+L25+M25 -> 13026.95 | P25: Margem Liq.
A26: Investimento amortizaçao | B26: ='Areas Sintetico atualizado'!C83 -> 2378.4892 | N26: =B26+C26+D26+E26+F26+G26+H26+I26+J26+K26+L26+M26 -> 2378.4892
A27: Margem liquida | B27: =B22-B23-B24-B25-B26 -> -20576.31 | C27: =C22-C23-C24-C25-C26 -> 0 | D27: =D22-D23-D24-D25-D26 -> 0 | E27: =E22-E23-E24-E25-E26 -> 0 | F27: =F22-F23-F24-F25-F26 -> 0 | G27: =G22-G23-G24-G25-G26 -> 0 | H27: =H22-H23-H24-H25-H26 -> 0 | I27: =I22-I23-I24-I25-I26 -> 0 | ... N27: =N22-N23-N24-N25-N26 -> -20576.31 | P27: =N27/N22 -> -0.23692779
B30: =B4+B13+B22 -> 279822 | C30: =C4+C13+C22 -> 0 | D30: =D4+D13+D22 -> 0 | E30: =E4+E13+E22 -> 0 | F30: =F4+F13+F22 -> 0 | G30: =G4+G13+G22 -> 0 | H30: =H4+H13+H22 -> 0 | I30: =I4+I13+I22 -> 0 | ... M30: =M4+M13+M22 -> 0 | N30: =B30+C30+D30+E30+F30+G30+H30+I30+J30+K30+L30+M30 -> 279822

Sheet DRE 2026
A1: DRE | C1: Janeiro | D1: Fevereiro | E1: Março | F1: Abril | G1: Maio | H1: Junho | I1: Julho | J1: Agosto | K1: Setembro | L1: Outubro | M1: Novembro | N1: Dezembro
A2: Resultado Institucional | C2: Orçado | D2: Orçado | E2: Orçado | F2: Orçado | G2: Orçado | H2: Orçado | I2: Orçado | J2: Orçado | K2: Orçado | L2: Orçado | M2: Orçado | N2: Orçado
A3: Faturamento | B3: =SUM(C3:N3) -> 8060000 | C3: 671666.67 | D3: 671666.67 | E3: 671666.67 | F3: 671666.67 | G3: 671666.67 | H3: 671666.67 | I3: 671666.67 | J3: 671666.67 | K3: 671666.67 | L3: 671666.67 | M3: 671666.67 | N3: 671666.67
A4: Despesas
A5: Custos Diretos | B5: =SUM(C5:N5) -> 2403882.6 | C5: =SUM(C6:C8) -> 213417.59 | D5: =SUM(D6:D8) -> 208717.59 | E5: =SUM(E6:E8) -> 196100.61 | F5: =SUM(F6:F8) -> 200900.61 | G5: =SUM(G6:G8) -> 196100.61 | H5: =SUM(H6:H8) -> 196100.61 | I5: =SUM(I6:I8) -> 200900.61 | J5: =SUM(J6:J8) -> 196100.61 | ... N5: =SUM(N6:N8) -> 198128.67
A6: Custo equipe - Contencioso | B6: =SUM(C6:N6) -> 881797.73 | C6: ='[2]Orçamento 2026'!D5 -> 74354.065 | D6: ='[2]Orçamento 2026'!E5 -> 72754.065 | E6: ='[2]Orçamento 2026'!F5 -> 72754.065 | F6: ='[2]Orçamento 2026'!G5 -> 74354.065 | G6: ='[2]Orçamento 2026'!H5 -> 72754.065 | H6: ='[2]Orçamento 2026'!I5 -> 72754.065 | I6: ='[2]Orçamento 2026'!J5 -> 74354.065 | J6: ='[2]Orçamento 2026'!K5 -> 72754.065 | ... N6: ='[2]Orçamento 2026'!O5 -> 73451.317
A7: Custo equipe - Econômico | B7: =SUM(C7:N7) -> 914114.75 | C7: ='[2]Orçamento 2026'!D28 -> 76879.165 | D7: ='[2]Orçamento 2026'!E28 -> 75379.165 | E7: ='[2]Orçamento 2026'!F28 -> 75379.165 | F7: ='[2]Orçamento 2026'!G28 -> 76979.165 | G7: ='[2]Orçamento 2026'!H28 -> 75379.165 | H7: ='[2]Orçamento 2026'!I28 -> 75379.165 | I7: ='[2]Orçamento 2026'!J28 -> 76979.165 | J7: ='[2]Orçamento 2026'!K28 -> 75379.165 | ... N7: ='[2]Orçamento 2026'!O28 -> 76467.423
A8: Custo equipe - Arbitragem e Compliance | B8: =SUM(C8:N8) -> 607970.16 | C8: ='[2]Orçamento 2026'!D53 -> 62184.36 | D8: ='[2]Orçamento 2026'!E53 -> 60584.36 | E8: ='[2]Orçamento 2026'!F53 -> 47967.38 | F8: ='[2]Orçamento 2026'!G53 -> 49567.38 | G8: ='[2]Orçamento 2026'!H53 -> 47967.38 | H8: ='[2]Orçamento 2026'!I53 -> 47967.38 | I8: ='[2]Orçamento 2026'!J53 -> 49567.38 | J8: ='[2]Orçamento 2026'!K53 -> 47967.38 | ... N8: ='[2]Orçamento 2026'!O53 -> 48209.927
A9: Despesas Indiretas | B9: =SUM(C9:N9) -> 1331793.8 | C9: =SUM(C10:C20) -> 102906.66 | D9: =SUM(D10:D20) -> 100790.33 | E9: =SUM(E10:E20) -> 128651.12 | F9: =SUM(F10:F20) -> 118391.12 | G9: =SUM(G10:G20) -> 108896.07 | H9: =SUM(H10:H20) -> 100270.33 | I9: =SUM(I10:I20) -> 108849.44 | J9: =SUM(J10:J20) -> 102160.57 | ... N9: =SUM(N10:N20) -> 136624.19
A10: Ocupação | B10: =SUM(C10:N10) -> 410635.68 | C10: ='[2]Orçamento 2026'!D73 -> 27197.48 | D10: ='[2]Orçamento 2026'!E73 -> 34236.38 | E10: ='[2]Orçamento 2026'!F73 -> 34236.38 | F10: ='[2]Orçamento 2026'!G73 -> 34236.38 | G10: ='[2]Orçamento 2026'!H73 -> 34236.38 | H10: ='[2]Orçamento 2026'!I73 -> 35213.24 | I10: ='[2]Orçamento 2026'!J73 -> 35213.24 | J10: ='[2]Orçamento 2026'!K73 -> 35213.24 | ... N10: ='[2]Orçamento 2026'!O73 -> 35213.24
A11: Telecomunicações | B11: =SUM(C11:N11) -> 10127.402 | C11: ='[2]Orçamento 2026'!D80 -> 890 | D11: ='[2]Orçamento 2026'!E80 -> 839.7638 | E11: ='[2]Orçamento 2026'!F80 -> 839.7638 | F11: ='[2]Orçamento 2026'!G80 -> 839.7638 | G11: ='[2]Orçamento 2026'!H80 -> 839.7638 | H11: ='[2]Orçamento 2026'!I80 -> 839.7638 | I11: ='[2]Orçamento 2026'!J80 -> 839.7638 | J11: ='[2]Orçamento 2026'!K80 -> 839.7638 | ... N11: ='[2]Orçamento 2026'!O80 -> 839.7638
A12: Despesas Gerais | B12: =SUM(C12:N12) -> 74921.85 | C12: ='[2]Orçamento 2026'!D83 -> 7255 | D12: ='[2]Orçamento 2026'!E83 -> 5505 | E12: ='[2]Orçamento 2026'!F83 -> 5742.205 | F12: ='[2]Orçamento 2026'!G83 -> 7292.205 | G12: ='[2]Orçamento 2026'!H83 -> 5742.205 | H12: ='[2]Orçamento 2026'!I83 -> 5683.605 | I12: ='[2]Orçamento 2026'!J83 -> 7333.605 | J12: ='[2]Orçamento 2026'!K83 -> 5683.605 | ... N12: ='[2]Orçamento 2026'!O83 -> 5783.605
A13: Consultoria | B13: =SUM(C13:N13) -> 244264.88 | C13: ='[2]Orçamento 2026'!D97 -> 23240.8 | D13: ='[2]Orçamento 2026'!E97 -> 23035.8 | E13: ='[2]Orçamento 2026'!F97 -> 22815.8 | F13: ='[2]Orçamento 2026'!G97 -> 18355.8 | G13: ='[2]Orçamento 2026'!H97 -> 18055.8 | H13: ='[2]Orçamento 2026'!I97 -> 18705.8 | I13: ='[2]Orçamento 2026'!J97 -> 18480.8 | J13: ='[2]Orçamento 2026'!K97 -> 19255.8 | ... N13: ='[2]Orçamento 2026'!O97 -> 22772.561
A14: Salários Administração | B14: =SUM(C14:N14) -> 82659.531 | C14: ='[2]Orçamento 2026'!D103 -> 6426.58 | D14: ='[2]Orçamento 2026'!E103 -> 6776.58 | E14: ='[2]Orçamento 2026'!F103 -> 6426.58 | F14: ='[2]Orçamento 2026'!G103 -> 6426.58 | G14: ='[2]Orçamento 2026'!H103 -> 6426.58 | H14: ='[2]Orçamento 2026'!I103 -> 6426.58 | I14: ='[2]Orçamento 2026'!J103 -> 6426.58 | J14: ='[2]Orçamento 2026'!K103 -> 6426.58 | ... N14: ='[2]Orçamento 2026'!O103 -> 8923.437
A15: Administrativas | B15: =SUM(C15:N15) -> 91084.465 | C15: ='[2]Orçamento 2026'!D111 -> 2996.8033 | D15: ='[2]Orçamento 2026'!E111 -> 2996.8033 | E15: ='[2]Orçamento 2026'!F111 -> 14690.387 | F15: ='[2]Orçamento 2026'!G111 -> 14690.387 | G15: ='[2]Orçamento 2026'!H111 -> 14695.337 | H15: ='[2]Orçamento 2026'!I111 -> 3001.3367 | I15: ='[2]Orçamento 2026'!J111 -> 5655.4486 | J15: ='[2]Orçamento 2026'!K111 -> 5691.5827 | ... N15: ='[2]Orçamento 2026'!O111 -> 5691.5827
A16: Taxas / Despesas Financeiras | B16: =SUM(C16:N16) -> 0
A17: Investimentos em Prospecção | B17: =SUM(C17:N17) -> 96000 | C17: ='[2]Orçamento 2026'!D124 -> 4500 | D17: ='[2]Orçamento 2026'!E124 -> 4500 | E17: ='[2]Orçamento 2026'!F124 -> 6000 | F17: ='[2]Orçamento 2026'!G124 -> 6000 | G17: ='[2]Orçamento 2026'!H124 -> 6000 | H17: ='[2]Orçamento 2026'!I124 -> 7500 | I17: ='[2]Orçamento 2026'!J124 -> 4500 | J17: ='[2]Orçamento 2026'!K124 -> 6000 | ... N17: ='[2]Orçamento 2026'!O124 -> 34500
A18: Endomarketing | B18: =SUM(C18:N18) -> 1200 | C18: ='[2]Orçamento 2026'!D151 -> 100 | D18: ='[2]Orçamento 2026'!E151 -> 100 | E18: ='[2]Orçamento 2026'!F151 -> 100 | F18: ='[2]Orçamento 2026'!G151 -> 100 | G18: ='[2]Orçamento 2026'!H151 -> 100 | H18: ='[2]Orçamento 2026'!I151 -> 100 | I18: ='[2]Orçamento 2026'!J151 -> 100 | J18: ='[2]Orçamento 2026'!K151 -> 100 | ... N18: ='[2]Orçamento 2026'!O151 -> 100
A19: ='[3]Areas Sintetico atualizado'!A21 -> Gestão do Conhecimento | B19: =SUM(C19:N19) -> 2300 | C19: ='[2]Orçamento 2026'!D145 -> 0 | D19: ='[2]Orçamento 2026'!E145 -> 0 | E19: ='[2]Orçamento 2026'!F145 -> 0 | F19: ='[2]Orçamento 2026'!G145 -> 150 | G19: ='[2]Orçamento 2026'!H145 -> 0 | H19: ='[2]Orçamento 2026'!I145 -> 0 | I19: ='[2]Orçamento 2026'!J145 -> 0 | J19: ='[2]Orçamento 2026'!K145 -> 150 | ... N19: ='[2]Orçamento 2026'!O145 -> 0
A20: Informática | B20: =SUM(C20:N20) -> 318600 | C20: ='[2]Orçamento 2026'!D161 -> 30300 | D20: ='[2]Orçamento 2026'!E161 -> 22800 | E20: ='[2]Orçamento 2026'!F161 -> 37800 | F20: ='[2]Orçamento 2026'!G161 -> 30300 | G20: ='[2]Orçamento 2026'!H161 -> 22800 | H20: ='[2]Orçamento 2026'!I161 -> 22800 | I20: ='[2]Orçamento 2026'!J161 -> 30300 | J20: ='[2]Orçamento 2026'!K161 -> 22800 | ... N20: ='[2]Orçamento 2026'!O161 -> 22800
A21: Resultado Bruto | B21: =B3-B5-B9 -> 4324323.6 | C21: =C3-C5-C9 -> 355342.42 | D21: =D3-D5-D9 -> 362158.75 | E21: =E3-E5-E9 -> 346914.94 | F21: =F3-F5-F9 -> 352374.94 | G21: =G3-G5-G9 -> 366669.99 | H21: =H3-H5-H9 -> 375295.73 | I21: =I3-I5-I9 -> 361916.62 | ... N21: =N3-N5-N9 -> 336913.81
A22: Margem de bruta | B22: =B21/B3 -> 0.53651657 | C22: =C21/C3 -> 0.52904578 | D22: =D21/D3 -> 0.53919417 | E22: =E21/E3 -> 0.51649867 | F22: =F21/F3 -> 0.52462771 | G22: =G21/G3 -> 0.54591066 | H22: =H21/H3 -> 0.55875295 | I22: =I21/I3 -> 0.53883368 | ... N22: =N21/N3 -> 0.50160865
A23: Impostos | B23: =C23+D23+E23+F23+G23+H23+I23+J23+K23+L23+M23+N23 -> 1809000 | C23: =(C3*15%)+50000 -> 150750 | D23: =(D3*15%)+50000 -> 150750 | E23: =(E3*15%)+50000 -> 150750 | F23: =(F3*15%)+50000 -> 150750 | G23: =(G3*15%)+50000 -> 150750 | H23: =(H3*15%)+50000 -> 150750 | I23: =(I3*15%)+50000 -> 150750 | J23: =(J3*15%)+50000 -> 150750 | ... N23: =(N3*15%)+50000 -> 150750
A24: Amortização | B24: =SUM(C24:N24) -> 97404 | C24: 8117 | D24: 8117 | E24: 8117 | F24: 8117 | G24: 8117 | H24: 8117 | I24: 8117 | J24: 8117 | K24: 8117 | L24: 8117 | M24: 8117 | N24: 8117
A25: Resultado Liquido após impostos | B25: =B21-B23-B24 -> 2417919.6 | C25: =C21-C23-C24 -> 196475.42 | D25: =D21-D23-D24 -> 203291.75 | E25: =E21-E23-E24 -> 188047.94 | F25: =F21-F23-F24 -> 193507.94 | G25: =G21-G23-G24 -> 207802.99 | H25: =H21-H23-H24 -> 216428.73 | I25: =I21-I23-I24 -> 203049.62 | ... N25: =N21-N23-N24 -> 178046.81
A26: Margem liquida | B26: =B25/B3 -> 0.29999002 | C26: =C25/C3 -> 0.29251923 | D26: =D25/D3 -> 0.30266762 | E26: =E25/E3 -> 0.27997212 | F26: =F25/F3 -> 0.28810116 | G26: =G25/G3 -> 0.30938411 | H26: =H25/H3 -> 0.3222264 | I26: =I25/I3 -> 0.30230713 | ... N26: =N25/N3 -> 0.2650821
A27: Reserva bônus | B27: =B25*10% -> 241791.96 | C27: =C25*10% -> 19647.542 | D27: =D25*10% -> 20329.175 | E27: =E25*10% -> 18804.794 | F27: =F25*10% -> 19350.794 | G27: =G25*10% -> 20780.299 | H27: =H25*10% -> 21642.873 | I27: =I25*10% -> 20304.962 | ... N27: =N25*10% -> 17804.681
A29: Rentabilidade | B29: =B6+B7+B8 -> 2403882.6 | C29: =C6+C7+C8 -> 213417.59 | D29: =D6+D7+D8 -> 208717.59 | E29: =E6+E7+E8 -> 196100.61 | F29: =F6+F7+F8 -> 200900.61 | G29: =G6+G7+G8 -> 196100.61 | H29: =H6+H7+H8 -> 196100.61 | I29: =I6+I7+I8 -> 200900.61 | ... N29: =N6+N7+N8 -> 198128.67
B30: =B9 -> 1331793.8 | C30: =C9 -> 102906.66 | D30: =D9 -> 100790.33 | E30: =E9 -> 128651.12 | F30: =F9 -> 118391.12 | G30: =G9 -> 108896.07 | H30: =H9 -> 100270.33 | I30: =I9 -> 108849.44 | ... N30: =N9 -> 136624.19
B31: =B29-B30 -> 1072088.8 | C31: =C29-C30 -> 110510.93 | D31: =D29-D30 -> 107927.26 | E31: =E29-E30 -> 67449.495 | F31: =F29-F30 -> 82509.495 | G31: =G29-G30 -> 87204.545 | H31: =H29-H30 -> 95830.285 | I31: =I29-I30 -> 92051.173 | ... N31: =N29-N30 -> 61504.477
B32: =B31/B3 -> 0.1330135 | C32: =C31/C3 -> 0.1645324 | D32: =D31/D3 -> 0.16068575 | E32: =E31/E3 -> 0.10042108 | F32: =F31/F3 -> 0.12284292 | G32: =G31/G3 -> 0.12983307 | H32: =H31/H3 -> 0.14267536 | I32: =I31/I3 -> 0.13704889 | ... N32: =N31/N3 -> 0.091569941
B96: =SUM(B97:B102) -> 0 | D96: =SUM(D97:D102) -> 0 | E96: =SUM(E97:E102) -> 0 | F96: =SUM(F97:F102) -> 0 | G96: =SUM(G97:G102) -> 0 | H96: =SUM(H97:H102) -> 0 | I96: =SUM(I97:I102) -> 0 | J96: =SUM(J97:J102) -> 0 | K96: =SUM(K97:K102) -> 0 | ... N96: =SUM(N97:N102) -> 0
A103: Assinaturas
B137: =SUM(B138:B141) -> 0 | D137: =SUM(D138:D141) -> 0 | E137: =SUM(E138:E141) -> 0 | F137: =SUM(F138:F141) -> 0 | G137: =SUM(G138:G141) -> 0 | H137: =SUM(H138:H141) -> 0 | I137: =SUM(I138:I141) -> 0 | J137: =SUM(J138:J141) -> 0 | K137: =SUM(K138:K141) -> 0 | ... N137: =SUM(N138:N141) -> 0
B168: =B4+B26+B51+B67+B73+B76+B90+B96+B103+B142+B152+B116+B137 -> 0.29999002 | D168: =D4+D26+D51+D67+D73+D76+D90+D96+D103+D142+D152+D116+D137 -> 0.30266762 | E168: =E4+E26+E51+E67+E73+E76+E90+E96+E103+E142+E152+E116+E137 -> 0.27997212 | F168: =F4+F26+F51+F67+F73+F76+F90+F96+F103+F142+F152+F116+F137 -> 0.28810116 | G168: =G4+G26+G51+G67+G73+G76+G90+G96+G103+G142+G152+G116+G137 -> 0.30938411 | H168: =H4+H26+H51+H67+H73+H76+H90+H96+H103+H142+H152+H116+H137 -> 0.3222264 | I168: =I4+I26+I51+I67+I73+I76+I90+I96+I103+I142+I152+I116+I137 -> 0.30230713 | J168: =J4+J26+J51+J67+J73+J76+J90+J96+J103+J142+J152+J116+J137 -> 0.31941214 | K168: =K4+K26+K51+K67+K73+K76+K90+K96+K103+K142+K152+K116+K137 -> 0.32127318 | ... N168: =N4+N26+N51+N67+N73+N76+N90+N96+N103+N142+N152+N116+N137 -> 0.2650821

Sheet Orçamento 2026
C1: 0.045
A2: Resultado Financeiro 2025 | B2: Soma JAN. a DEZ. | D2: Janeiro | E2: Fevereiro | F2: Março | G2: Abril | H2: Maio | I2: Junho | J2: Julho | K2: Agosto | L2: Setembro | M2: Outubro | N2: Novembro | O2: Dezembro
A3: Movimentação de Entradas | B3: =SUM(C3:O3) -> 8060000 | D3: 671666.67 | E3: 671666.67 | F3: 671666.67 | G3: 671666.67 | H3: 671666.67 | I3: 671666.67 | J3: 671666.67 | K3: 671666.67 | L3: 671666.67 | M3: 671666.67 | N3: 671666.67 | O3: 671666.67
A4: Receita de honorários | B4: =SUM(D4:O4) -> 0
A5: Custo equipe - Contencioso | B5: =SUM(D5:O5) -> 881797.73 | D5: =SUM(D6:D27) -> 74354.065 | E5: =SUM(E6:E27) -> 72754.065 | F5: =SUM(F6:F27) -> 72754.065 | G5: =SUM(G6:G27) -> 74354.065 | H5: =SUM(H6:H27) -> 72754.065 | I5: =SUM(I6:I27) -> 72754.065 | J5: =SUM(J6:J27) -> 74354.065 | K5: =SUM(K6:K27) -> 72754.065 | ... O5: =SUM(O6:O27) -> 73451.317
A6: Daniel Costa Caselta - Distribuição Mensal Fixa | B6: =SUM(D6:O6) -> 280548 | D6: ='[2]Tabela 2025 2026'!Q13 -> 23379 | E6: =D6 -> 23379 | F6: =E6 -> 23379 | G6: =F6 -> 23379 | H6: =G6 -> 23379 | I6: =H6 -> 23379 | J6: =I6 -> 23379 | K6: =J6 -> 23379 | L6: =K6 -> 23379 | ... O6: =N6 -> 23379
A7: Daniel Costa Caselta - Pro labore | B7: =SUM(D7:O7) -> 19452 | D7: ='[2]Tabela 2025 2026'!M14 -> 1621 | E7: =D7 -> 1621 | F7: =E7 -> 1621 | G7: =F7 -> 1621 | H7: =G7 -> 1621 | I7: =H7 -> 1621 | J7: =I7 -> 1621 | K7: =J7 -> 1621 | L7: =K7 -> 1621 | ... O7: =N7 -> 1621
A8: Daniel Costa Caselta - Convenio Medico | B8: =SUM(D8:O8) -> 21825.998 | D8: 1794.65 | E8: =D8 -> 1794.65 | F8: =E8 -> 1794.65 | G8: =F8 -> 1794.65 | H8: =G8 -> 1794.65 | I8: =H8 -> 1794.65 | J8: =I8 -> 1794.65 | K8: =J8 -> 1794.65 | L8: =K8 -> 1794.65 | M8: =L8+(L8*[2]Premissas!B4) -> 2063.8475 | N8: 1804.65 | O8: 1805.65
A9: Aurelio Marchini Santos - Distribuição Mensal Fixa | B9: =SUM(D9:O9) -> 140274 | D9: ='[2]Tabela 2025 2026'!Q13/2 -> 11689.5 | E9: =D9 -> 11689.5 | F9: =E9 -> 11689.5 | G9: =F9 -> 11689.5 | H9: =G9 -> 11689.5 | I9: =H9 -> 11689.5 | J9: =I9 -> 11689.5 | K9: =J9 -> 11689.5 | L9: =K9 -> 11689.5 | ... O9: =N9 -> 11689.5
A10: Aurelio Marchini Santos- Pro labore | B10: =SUM(D10:O10) -> 9726 | D10: ='[2]Tabela 2025 2026'!M13/2 -> 810.5 | E10: =D10 -> 810.5 | F10: =E10 -> 810.5 | G10: =F10 -> 810.5 | H10: =G10 -> 810.5 | I10: =H10 -> 810.5 | J10: =I10 -> 810.5 | K10: =J10 -> 810.5 | L10: =K10 -> 810.5 | ... O10: =N10 -> 810.5
A11: Aurelio Marchini Santos - Convenio Medico | B11: =SUM(D11:O11) -> 20483.176 | D11: =(3290.47/2) -> 1645.235 | E11: =D11 -> 1645.235 | F11: =E11 -> 1645.235 | G11: =F11 -> 1645.235 | H11: =G11 -> 1645.235 | I11: =H11 -> 1645.235 | J11: =I11 -> 1645.235 | K11: =J11 -> 1645.235 | L11: =K11 -> 1645.235 | M11: =(3290.47/2)*[2]Premissas!B4+'Orçamento 2026'!L11 -> 1892.0202 | N11: =M11 -> 1892.0202 | O11: =N11 -> 1892.0202
A12: Beatriz Baes Xavier - Distribuição Mensal Fixa | B12: =SUM(D12:O12) -> 90448.8 | D12: ='[2]Tabela 2025 2026'!Q4 -> 7537.4 | E12: =D12 -> 7537.4 | F12: =E12 -> 7537.4 | G12: =F12 -> 7537.4 | H12: =G12 -> 7537.4 | I12: =H12 -> 7537.4 | J12: =I12 -> 7537.4 | K12: =J12 -> 7537.4 | L12: =K12 -> 7537.4 | ... O12: =N12 -> 7537.4
A13: Beatriz Baes Xavier - Pro Labore | B13: =SUM(D13:O13) -> 19452 | D13: ='[2]Tabela 2025 2026'!M4 -> 1621 | E13: =D13 -> 1621 | F13: =E13 -> 1621 | G13: =F13 -> 1621 | H13: =G13 -> 1621 | I13: =H13 -> 1621 | J13: =I13 -> 1621 | K13: =J13 -> 1621 | L13: =K13 -> 1621 | ... O13: =N13 -> 1621
A14: Beatriz Baes Xavier - Convenio Medico | B14: =SUM(D14:O14) -> 16344.36 | D14: 1312.8 | E14: =D14 -> 1312.8 | F14: =E14 -> 1312.8 | G14: =F14 -> 1312.8 | H14: =G14 -> 1312.8 | I14: =H14 -> 1312.8 | J14: =I14 -> 1312.8 | K14: =J14 -> 1312.8 | L14: =K14 -> 1312.8 | M14: =1312.8*[2]Premissas!B4+'Orçamento 2026'!L14 -> 1509.72 | N14: =M14 -> 1509.72 | O14: =N14 -> 1509.72
A15: Beatriz Baes Xavier - Despesas Extras - Cartao Predio | B15: =SUM(D15:O15) -> 0
A16: Beatriz Baes Xavier - Reajuste de Distribuição Mensal Fixa | B16: =SUM(D16:O16) -> 0
A17: Isabel de Almeida Rego Campinho - Distribuição Mensal Fixa | B17: =SUM(D17:O17) -> 187260 | D17: ='[2]Tabela 2025 2026'!Q9 -> 15605 | E17: =D17 -> 15605 | F17: =E17 -> 15605 | G17: =F17 -> 15605 | H17: =G17 -> 15605 | I17: =H17 -> 15605 | J17: =I17 -> 15605 | K17: =J17 -> 15605 | L17: =K17 -> 15605 | ... O17: =N17 -> 15605
A18: Isabel de Almeida Rego Campinho - Pro Labore | B18: =SUM(D18:O18) -> 19452 | D18: ='[2]Tabela 2025 2026'!M9 -> 1621 | E18: =D18 -> 1621 | F18: =E18 -> 1621 | G18: =F18 -> 1621 | H18: =G18 -> 1621 | I18: =H18 -> 1621 | J18: =I18 -> 1621 | K18: =J18 -> 1621 | L18: =K18 -> 1621 | ... O18: =N18 -> 1621
A19: Isabel de Almeida Rego Campinho - Convenio Medico | B19: =SUM(D19:O19) -> 20131.401 | D19: 1616.98 | E19: 1616.98 | F19: 1616.98 | G19: 1616.98 | H19: 1616.98 | I19: 1616.98 | J19: 1616.98 | K19: 1616.98 | L19: 1616.98 | M19: =1616.98*[2]Premissas!B4+'Orçamento 2026'!L19 -> 1859.527 | N19: =M19 -> 1859.527 | O19: =N19 -> 1859.527
A20: Isabel de Almeida Rego Campinho - Reajuste de Distribuição Mensal Fixa | B20: =SUM(D20:O20) -> 0
A21: Joao Victor estagiario | B21: =SUM(D21:O21) -> 26400 | D21: 2200 | E21: 2200 | F21: 2200 | G21: 2200 | H21: 2200 | I21: 2200 | J21: 2200 | K21: 2200 | L21: 2200 | M21: 2200 | N21: 2200 | O21: 2200
A22: Joao Victor VT | B22: =SUM(D22:O22) -> 3600 | D22: 300 | E22: 300 | F22: 300 | G22: 300 | H22: 300 | I22: 300 | J22: 300 | K22: 300 | L22: 300 | M22: 300 | N22: 300 | O22: 300
A23: ISS Trimestral | B23: =SUM(D23:O23) -> 6400 | D23: 1600 | G23: 1600 | J23: 1600 | M23: 1600
A24: Seguro de vida | B24: =SUM(D24:O24) -> 0
A25: Vale Refeição | B25: =SUM(D25:O25) -> 0
A26: Amortização | B26: =SUM(D26:O26) -> 0
A27: Participação/comissão/repasse - Contencioso | B27: =SUM(D27:O27) -> 0
A28: Custo equipe - Econômico | B28: =SUM(D28:O28) -> 914114.75 | D28: =SUM(D29:D51) -> 76879.165 | E28: =SUM(E29:E51) -> 75379.165 | F28: =SUM(F29:F51) -> 75379.165 | G28: =SUM(G29:G51) -> 76979.165 | H28: =SUM(H29:H51) -> 75379.165 | I28: =SUM(I29:I51) -> 75379.165 | J28: =SUM(J29:J51) -> 76979.165 | K28: =SUM(K29:K51) -> 75379.165 | ... O28: =SUM(O29:O51) -> 76467.423
A29: Ricardo Franco Botelho - Distribuição Mensal Fixa | B29: =SUM(D29:O29) -> 280548 | D29: ='[2]Tabela 2025 2026'!Q16 -> 23379 | E29: =D29 -> 23379 | F29: =E29 -> 23379 | G29: =F29 -> 23379 | H29: =G29 -> 23379 | I29: =H29 -> 23379 | J29: =I29 -> 23379 | K29: =J29 -> 23379 | L29: =K29 -> 23379 | ... O29: =N29 -> 23379
A30: Ricardo Franco Botelho - Pro labore | B30: =SUM(D30:O30) -> 19452 | D30: ='[2]Tabela 2025 2026'!M16 -> 1621 | E30: =D30 -> 1621 | F30: =E30 -> 1621 | G30: =F30 -> 1621 | H30: =G30 -> 1621 | I30: =H30 -> 1621 | J30: =I30 -> 1621 | K30: =J30 -> 1621 | L30: =K30 -> 1621 | ... O30: =N30 -> 1621
A31: Ricardo Franco Botelho - Convenio Medico | B31: =SUM(D31:O31) -> 30320.481 | D31: 2435.38 | E31: 2435.38 | F31: 2435.38 | G31: 2435.38 | H31: 2435.38 | I31: 2435.38 | J31: 2435.38 | K31: 2435.38 | L31: 2435.38 | M31: =2435.38*[2]Premissas!B4+'Orçamento 2026'!L31 -> 2800.687 | N31: =M31 -> 2800.687 | O31: =N31 -> 2800.687
A32: Aurelio Marchini Santos - Distribuição Mensal Fixa | B32: =SUM(D32:O32) -> 140274 | D32: ='[2]Tabela 2025 2026'!Q13/2 -> 11689.5 | E32: =D32 -> 11689.5 | F32: =E32 -> 11689.5 | G32: =F32 -> 11689.5 | H32: =G32 -> 11689.5 | I32: =H32 -> 11689.5 | J32: =I32 -> 11689.5 | K32: =J32 -> 11689.5 | L32: =K32 -> 11689.5 | ... O32: =N32 -> 11689.5
A33: Aurelio Marchini Santos- Pro labore | B33: =SUM(D33:O33) -> 9726 | D33: ='[2]Tabela 2025 2026'!M13/2 -> 810.5 | E33: =D33 -> 810.5 | F33: =E33 -> 810.5 | G33: =F33 -> 810.5 | H33: =G33 -> 810.5 | I33: =H33 -> 810.5 | J33: =I33 -> 810.5 | K33: =J33 -> 810.5 | L33: =K33 -> 810.5 | ... O33: =N33 -> 810.5
A34: Aurelio Marchini Santos - Convenio Medico | B34: =SUM(D34:O34) -> 19742.82 | D34: =(3290.47/2) -> 1645.235 | E34: =(3290.47/2) -> 1645.235 | F34: =(3290.47/2) -> 1645.235 | G34: =(3290.47/2) -> 1645.235 | H34: =(3290.47/2) -> 1645.235 | I34: =(3290.47/2) -> 1645.235 | J34: =(3290.47/2) -> 1645.235 | K34: =(3290.47/2) -> 1645.235 | L34: =(3290.47/2) -> 1645.235 | M34: =(3290.47/2)*[2]Premissas!B30+'Orçamento 2026'!L34 -> 1645.235 | N34: =M34 -> 1645.235 | O34: =N34 -> 1645.235
A35: Aurelio Marchini Santos - AASP | B35: =SUM(D35:O35) -> 1100 | E35: 100 | F35: 100 | G35: 100 | H35: 100 | I35: 100 | J35: 100 | K35: 100 | L35: 100 | M35: 100 | N35: 100 | O35: 100
A36: Bruno Micalli Pedrinelli - Distribuição Mensal Fixa | B36: =SUM(D36:O36) -> 96454.56 | D36: ='[2]Tabela 2025 2026'!Q5 -> 8037.88 | E36: =D36 -> 8037.88 | F36: =E36 -> 8037.88 | G36: =F36 -> 8037.88 | H36: =G36 -> 8037.88 | I36: =H36 -> 8037.88 | J36: =I36 -> 8037.88 | K36: =J36 -> 8037.88 | L36: =K36 -> 8037.88 | ... O36: =N36 -> 8037.88
A37: Bruno Micalli Pedrinelli - Pro Labore | B37: =SUM(D37:O37) -> 19452 | D37: ='[2]Tabela 2025 2026'!M5 -> 1621 | E37: =D37 -> 1621 | F37: =E37 -> 1621 | G37: =F37 -> 1621 | H37: =G37 -> 1621 | I37: =H37 -> 1621 | J37: =I37 -> 1621 | K37: =J37 -> 1621 | L37: =K37 -> 1621 | ... O37: =N37 -> 1621
A38: Bruno Micalli Pedrinelli - Convenio Medico | B38: =SUM(D38:O38) -> 16344.36 | D38: 1312.8 | E38: 1312.8 | F38: 1312.8 | G38: 1312.8 | H38: 1312.8 | I38: 1312.8 | J38: 1312.8 | K38: 1312.8 | L38: 1312.8 | M38: =1312.8*[2]Premissas!$B$4+'Orçamento 2026'!L38 -> 1509.72 | N38: =M38 -> 1509.72 | O38: =N38 -> 1509.72
A39: Bruno Micalli Pedrinelli - Reajuste de Distribuição Mensal Fixa | B39: =SUM(D39:O39) -> 0
A40: Elisa Hime Funari - Distribuição Mensal Fixa | B40: =SUM(D40:O40) -> 142548 | D40: ='[2]Tabela 2025 2026'!Q7 -> 11879 | E40: =D40 -> 11879 | F40: =E40 -> 11879 | G40: =F40 -> 11879 | H40: =G40 -> 11879 | I40: =H40 -> 11879 | J40: =I40 -> 11879 | K40: =J40 -> 11879 | L40: =K40 -> 11879 | ... O40: =N40 -> 11879
...

Sheet Base_Resultado Mensal_V2
A2: Resultado Financeiro 2025 | B2: ANUAL | C2: Janeiro | D2: Fevereiro | E2: Março | F2: Abril | G2: Maio | H2: Junho | I2: Julho | J2: Agosto | K2: Setembro | L2: Outubro | M2: Novembro | N2: Dezembro
A3: Movimentação de Entradas | C3: =SUM(C4:C4) -> 279821.07 | D3: =SUM(D4:D4) -> 319233.58 | E3: =SUM(E4:E4) -> 0 | F3: =SUM(F4:F4) -> 0 | G3: =SUM(G4:G4) -> 0 | H3: =SUM(H4:H4) -> 0 | I3: =SUM(I4:I4) -> 0 | J3: =SUM(J4:J4) -> 0 | ... N3: =SUM(N4:N4) -> 0
A4: Receita de honorários | B4: =SUM(C4:N4) -> 599054.65 | C4: 279821.07 | D4: 319233.58 | O4: =C4+D4+E4+F4+G4+H4+I4+J4+K4+L4+M4+N4 -> 599054.65
A5: Custo equipe - Contencioso | B5: =SUM(C5:N5) -> 149918.66 | C5: =SUM(C6:C27) -> 73576.315 | D5: =SUM(D6:D27) -> 76342.345 | E5: =SUM(E6:E27) -> 0 | F5: =SUM(F6:F27) -> 0 | G5: =SUM(G6:G27) -> 0 | H5: =SUM(H6:H27) -> 0 | I5: =SUM(I6:I27) -> 0 | J5: =SUM(J6:J27) -> 0 | ... N5: =SUM(N6:N27) -> 0 | O5: =C5+D5+E5+F5+G5+H5+I5+J5+K5+L5+M5+N5 -> 149918.66
A6: Aurelio Marchini Santos - Convenio Medico | B6: =SUM(C6:N6) -> 3182.83 | C6: =3182.83/2 -> 1591.415 | D6: =3182.83/2 -> 1591.415 | O6: =C6+D6+E6+F6+G6+H6+I6+J6+K6+L6+M6+N6 -> 3182.83
A7: Aurelio Marchini Santos - Distribuição Mensal Fixa | B7: =SUM(C7:N7) -> 23379 | C7: =12500-C8 -> 11689.5 | D7: =12500-D8 -> 11689.5 | O7: =C7+D7+E7+F7+G7+H7+I7+J7+K7+L7+M7+N7 -> 23379
A8: Aurelio Marchini Santos- Pro labore | B8: =SUM(C8:N8) -> 1621 | C8: 810.5 | D8: 810.5 | O8: =C8+D8+E8+F8+G8+H8+I8+J8+K8+L8+M8+N8 -> 1621
A9: Aurelio Marchini Santos- AASP | B9: =SUM(C9:N9) -> 54.35 | D9: =108.7/2 -> 54.35
A10: Beatriz Baes Xavier - Convenio Medico | B10: =SUM(C10:N10) -> 2538.92 | C10: 1269.46 | D10: 1269.46 | O10: =C10+D10+E10+F10+G10+H10+I10+J10+K10+L10+M10+N10 -> 2538.92
A11: Beatriz Baes Xavier - Despesas Extras - Cartao Predio | B11: =SUM(C11:N11) -> 0 | O11: =C11+D11+E11+F11+G11+H11+I11+J11+K11+L11+M11+N11 -> 0
A12: Beatriz Baes Xavier - Distribuição Mensal Fixa | B12: =SUM(C12:N12) -> 14556.4 | C12: =8640-C13 -> 7019 | D12: =9158.4-D13 -> 7537.4 | O12: =C12+D12+E12+F12+G12+H12+I12+J12+K12+L12+M12+N12 -> 14556.4
A13: Beatriz Baes Xavier - Pro Labore | B13: =SUM(C13:N13) -> 3242 | C13: 1621 | D13: 1621 | O13: =C13+D13+E13+F13+G13+H13+I13+J13+K13+L13+M13+N13 -> 3242
A14: Beatriz Baes Xavier - Reajuste de Distribuição Mensal Fixa | B14: =SUM(C14:N14) -> 518.4 | D14: 518.4 | O14: =C14+D14+E14+F14+G14+H14+I14+J14+K14+L14+M14+N14 -> 518.4
A15: Daniel Costa Caselta - Convenio Medico | B15: =SUM(C15:N15) -> 3472.28 | C15: 1736.14 | D15: 1736.14 | O15: =C15+D15+E15+F15+G15+H15+I15+J15+K15+L15+M15+N15 -> 3472.28
A16: Daniel Costa Caselta - Distribuição Mensal Fixa | B16: =SUM(C16:N16) -> 46758 | C16: =25000-C17 -> 23379 | D16: =25000-D17 -> 23379 | O16: =C16+D16+E16+F16+G16+H16+I16+J16+K16+L16+M16+N16 -> 46758
A17: Daniel Costa Caselta - Pro labore | B17: =SUM(C17:N17) -> 3242 | C17: 1621 | D17: 1621 | O17: =C17+D17+E17+F17+G17+H17+I17+J17+K17+L17+M17+N17 -> 3242
A18: Daniel Costa Caselta - AASP | B18: =SUM(C18:N18) -> 206.4 | C18: 97.7 | D18: 108.7 | O18: =C18+D18+E18+F18+G18+H18+I18+J18+K18+L18+M18+N18 -> 206.4
A19: Isabel de Almeida Rego Campinho - Convenio Medico | B19: =SUM(C19:N19) -> 3128.16 | C19: 1564.08 | D19: 1564.08 | O19: =C19+D19+E19+F19+G19+H19+I19+J19+K19+L19+M19+N19 -> 3128.16
A20: Isabel de Almeida Rego Campinho - Distribuição Mensal Fixa | B20: =SUM(C20:N20) -> 29644 | C20: =15660-C21 -> 14039 | D20: =17226-D21 -> 15605 | O20: =C20+D20+E20+F20+G20+H20+I20+J20+K20+L20+M20+N20 -> 29644
A21: Isabel de Almeida Rego Campinho - Pro Labore | B21: =SUM(C21:N21) -> 3242 | C21: 1621 | D21: 1621 | O21: =C21+D21+E21+F21+G21+H21+I21+J21+K21+L21+M21+N21 -> 3242
A22: Isabel de Almeida Rego Campinho - Reajuste de Distribuição Mensal Fixa | B22: =SUM(C22:N22) -> 1566 | D22: 1566 | O22: =C22+D22+E22+F22+G22+H22+I22+J22+K22+L22+M22+N22 -> 1566
A23: João Victor Santos de Oliveira - Bolsa auxilio / IR Estagiários | B23: =SUM(C23:N23) -> 5600 | C23: 2800 | D23: 2800 | O23: =C23+D23+E23+F23+G23+H23+I23+J23+K23+L23+M23+N23 -> 5600
A24: João Victor Santos de Oliveira - Seguro de Vida | B24: =SUM(C24:N24) -> 0 | O24: =C24+D24+E24+F24+G24+H24+I24+J24+K24+L24+M24+N24 -> 0
A25: ISS Trimestral | B25: =SUM(C25:N25) -> 1719.72 | C25: =382.16*4+191.08 -> 1719.72 | O25: =C25+D25+E25+F25+G25+H25+I25+J25+K25+L25+M25+N25 -> 1719.72
A26: Vale Refeição | B26: =SUM(C26:N26) -> 1844 | C26: 829.8 | D26: 1014.2 | O26: =C26+D26+E26+F26+G26+H26+I26+J26+K26+L26+M26+N26 -> 1844
A27: Vale Transporte | B27: =SUM(C27:N27) -> 403.2 | C27: 168 | D27: 235.2 | O27: =C27+D27+E27+F27+G27+H27+I27+J27+K27+L27+M27+N27 -> 403.2
A28: Participação/Comissão - Contencioso | B28: =SUM(C28:N28) -> 0 | O28: =C28+D28+E28+F28+G28+H28+I28+J28+K28+L28+M28+N28 -> 0
A29: Repasse - Contencioso | B29: =SUM(C29:N29) -> 0 | O29: =C29+D29+E29+F29+G29+H29+I29+J29+K29+L29+M29+N29 -> 0
A30: Custo equipe - Econômico | B30: =SUM(B31:B56) -> 157817.78 | C30: =SUM(C31:C55) -> 76041.035 | D30: =SUM(D31:D55) -> 80276.745 | E30: =SUM(E31:E55) -> 0 | F30: =SUM(F31:F55) -> 0 | G30: =SUM(G31:G55) -> 0 | H30: =SUM(H31:H55) -> 0 | I30: =SUM(I31:I55) -> 0 | J30: =SUM(J31:J55) -> 0 | ... N30: =SUM(N31:N55) -> 0 | O30: =C30+D30+E30+F30+G30+H30+I30+J30+K30+L30+M30+N30 -> 156317.78
A31: Andrielly da Silva Gonsalves - Convenio Medico | B31: =SUM(C31:N31) -> 1834.38 | C31: 1269.46 | D31: 564.92 | O31: =C31+D31+E31+F31+G31+H31+I31+J31+K31+L31+M31+N31 -> 1834.38
A32: Andrielly da Silva Gonsalves - Distribuição Mensal Fixa | B32: =SUM(C32:N32) -> 7678 | C32: =5200-C33 -> 3579 | D32: =5720-D33 -> 4099 | O32: =C32+D32+E32+F32+G32+H32+I32+J32+K32+L32+M32+N32 -> 7678
A33: Andrielly da Silva Gonsalves - Pro Labore | B33: =SUM(C33:N33) -> 3242 | C33: 1621 | D33: 1621 | O33: =C33+D33+E33+F33+G33+H33+I33+J33+K33+L33+M33+N33 -> 3242
A34: Andrielly da Silva Gonsalves - Subsidio de Pós | B34: =SUM(C34:N34) -> 3018 | D34: =1509+1509 -> 3018 | O34: =C34+D34+E34+F34+G34+H34+I34+J34+K34+L34+M34+N34 -> 3018
A35: Andrielly da Silva Gonsalves - Reajuste de Distribuição Mensal Fixa | B35: =SUM(C35:N35) -> 520 | D35: 520 | O35: =C35+D35+E35+F35+G35+H35+I35+J35+K35+L35+M35+N35 -> 520
A36: Aurelio Marchini Santos - AASP | B36: =SUM(C36:N36) -> 152.05 | C36: 97.7 | D36: =108.7/2 -> 54.35 | O36: =C36+D36+E36+F36+G36+H36+I36+J36+K36+L36+M36+N36 -> 152.05
A37: Aurelio Marchini Santos - Convenio Medico | B37: =SUM(C37:N37) -> 3182.83 | C37: =3182.83/2 -> 1591.415 | D37: =3182.83/2 -> 1591.415 | O37: =C37+D37+E37+F37+G37+H37+I37+J37+K37+L37+M37+N37 -> 3182.83
A38: Aurelio Marchini Santos - Distribuição Mensal Fixa | B38: =SUM(C38:N38) -> 23379 | C38: =12500-C39 -> 11689.5 | D38: =12500-D39 -> 11689.5 | O38: =C38+D38+E38+F38+G38+H38+I38+J38+K38+L38+M38+N38 -> 23379
A39: Aurelio Marchini Santos- Pro labore | B39: =SUM(C39:N39) -> 1621 | C39: 810.5 | D39: 810.5 | O39: =C39+D39+E39+F39+G39+H39+I39+J39+K39+L39+M39+N39 -> 1621
A40: Bruno Micalli Pedrinelli - Convenio Medico | B40: =SUM(C40:N40) -> 1834.38 | C40: 1269.46 | D40: 564.92 | O40: =C40+D40+E40+F40+G40+H40+I40+J40+K40+L40+M40+N40 -> 1834.38
A41: Bruno Micalli Pedrinelli - Distribuição Mensal Fixa | B41: =SUM(C41:N41) -> 15040.88 | C41: =8624-C42 -> 7003 | D41: =9658.88-D42 -> 8037.88 | O41: =C41+D41+E41+F41+G41+H41+I41+J41+K41+L41+M41+N41 -> 15040.88
...

Sheet Areas Sintetico atualizado
A1: DRE 2025 | B1: Janeiro | F1: Fevereiro | O1: 11 | Q1: CHECK
A2: Resultado Institucional | B2: Orçado | C2: Realizado | D2: Variação Mensal | E2: Desvio% | F2: Orçado | G2: Realizado | H2: Variação Mensal | I2: Desvio% | J2: Orçado YTG | K2: Orçado YTD | L2: Realizado | M2: Variação | N2: Variação Mensal | O2: YTG
A3: Faturamento | B3: ='DRE 2026'!C3 -> 671666.67 | C3: 444545.69 | D3: =+C3-B3 -> -227120.98 | E3: =C3/B3 -> 0.66185462 | F3: ='DRE 2026'!D3 -> 671666.67 | G3: 534752.84 | H3: =+G3-F3 -> -136913.83 | I3: =G3/F3 -> 0.79615807 | J3: ='DRE 2026'!B3 -> 8060000 | K3: ='DRE 2026'!C3+'DRE 2026'!D3 -> 1343333.3 | L3: =C3 -> 444545.69 | M3: =L3-K3 -> -898787.65 | N3: =L3/K3 -> 0.33092731 | O3: =J3-L3 -> 7615454.3 | Q3: =C3 -> 444545.69 | R3: =L3-Q3 -> 0
A4: Receita | C4: ='Base_Resultado Mensal_V2'!C4 -> 279821.07 | G4: ='Base_Resultado Mensal_V2'!D4 -> 319233.58 | K4: ='DRE 2026'!C3+'DRE 2026'!D3 -> 1343333.3 | L4: ='Base_Resultado Mensal_V2'!C4+'Base_Resultado Mensal_V2'!D4+'Base_Resultado Mensal_V2'!E4+'Base_Resultado Mensal_V2'!F4+'Base_Resultado Mensal_V2'!G4+'Base_Resultado Mensal_V2'!H4+'Base_Resultado Mensal_V2'!I4+'Base_Resultado Mensal_V2'!J4+'Base_Resultado Mensal_V2'!K4+'Base_Resultado Mensal_V2'!L4+'Base_Resultado Mensal_V2'!M4+'Base_Resultado Mensal_V2'!N4 -> 599054.65 | M4: =L4-K3 -> -744278.69 | Q4: ='Base_Resultado Mensal_V2'!O4 -> 599054.65 | R4: =L4-Q4 -> 0
A5: Despesas | B5: Orçado | C5: Realizado | D5: Variação Mensal | E5: Variação Mensal | F5: Orçado | G5: Realizado | H5: Variação Mensal | I5: Variação Mensal | N5: Variação Mensal
A6: Custos Diretos | B6: =SUM(B7:B11) -> 213417.59 | C6: =SUM(C7:C12) -> 211630.52 | D6: =+B6-C6 -> 1787.07 | F6: =SUM(F7:F11) -> 208717.59 | G6: =SUM(G7:G12) -> 219913.43 | H6: =+F6-G6 -> -11195.84 | J6: =SUM(J7:J11) -> 2403882.6 | K6: =SUM(K7:K11) -> 213417.59 | L6: =L7+L8+L9+L10+L11+L12 -> 211630.52 | M6: =K6-L6 -> 1787.07 | N6: =L6/K6 -> 0.99162642 | O6: =J6-L6 -> 2192252.1 | Q6: =SUM(Q7:Q12) -> 431543.95 | R6: =L6-Q6 -> -219913.43
A7: =+'Base_Resultado Mensal_V2'!A5 -> Custo equipe - Contencioso | B7: ='DRE 2026'!C6 -> 74354.065 | C7: ='Base_Resultado Mensal_V2'!C5 -> 73576.315 | D7: =+B7-C7 -> 777.75 | E7: =C7/B7 -> 0.98953991 | F7: ='DRE 2026'!D6 -> 72754.065 | G7: ='Base_Resultado Mensal_V2'!D5 -> 76342.345 | H7: =+F7-G7 -> -3588.28 | I7: =G7/F7 -> 1.0493207 | J7: ='DRE 2026'!B6 -> 881797.73 | K7: ='DRE 2026'!C6 -> 74354.065 | L7: =C7 -> 73576.315 | M7: =K7-L7 -> 777.75 | N7: =L7/K7 -> 0.98953991 | O7: =J7-L7 -> 808221.42 | Q7: ='Base_Resultado Mensal_V2'!O5 -> 149918.66 | R7: =L7-Q7 -> -76342.345
A8: ='Base_Resultado Mensal_V2'!A28 -> Participação/Comissão - Contencioso | C8: ='Base_Resultado Mensal_V2'!C28+'Base_Resultado Mensal_V2'!C29 -> 0 | G8: ='Base_Resultado Mensal_V2'!D28+'Base_Resultado Mensal_V2'!D29 -> 0 | L8: =C8 -> 0 | Q8: ='Base_Resultado Mensal_V2'!O28+'Base_Resultado Mensal_V2'!O29 -> 0 | R8: =L8-Q8 -> 0
A9: =+'Base_Resultado Mensal_V2'!A30 -> Custo equipe - Econômico | B9: ='DRE 2026'!C7 -> 76879.165 | C9: ='Base_Resultado Mensal_V2'!C30 -> 76041.035 | D9: =+B9-C9 -> 838.13 | E9: =C9/B9 -> 0.98909809 | F9: ='DRE 2026'!D7 -> 75379.165 | G9: ='Base_Resultado Mensal_V2'!D30 -> 80276.745 | H9: =+F9-G9 -> -4897.58 | I9: =G9/F9 -> 1.0649726 | J9: ='DRE 2026'!B7 -> 914114.75 | K9: ='DRE 2026'!C7 -> 76879.165 | L9: =C9 -> 76041.035 | M9: =K9-L9 -> 838.13 | N9: =L9/K9 -> 0.98909809 | O9: =J9-L9 -> 838073.72 | Q9: ='Base_Resultado Mensal_V2'!O30 -> 156317.78 | R9: =L9-Q9 -> -80276.745
A10: ='Base_Resultado Mensal_V2'!A56 -> Participação/comissão - Economico | C10: ='Base_Resultado Mensal_V2'!C28+'Base_Resultado Mensal_V2'!C29 -> 0 | G10: ='Base_Resultado Mensal_V2'!D56+'Base_Resultado Mensal_V2'!D57 -> 1500 | L10: =C10 -> 0 | Q10: ='Base_Resultado Mensal_V2'!O56+'Base_Resultado Mensal_V2'!O57 -> 1500 | R10: =L10-Q10 -> -1500
A11: =+'Base_Resultado Mensal_V2'!A58 -> Custo equipe - Arbitragem e Compliance | B11: ='DRE 2026'!C8 -> 62184.36 | C11: ='Base_Resultado Mensal_V2'!C58 -> 62013.17 | D11: =+B11-C11 -> 171.19 | E11: =C11/B11 -> 0.99724706 | F11: ='DRE 2026'!D8 -> 60584.36 | G11: ='Base_Resultado Mensal_V2'!D58 -> 61794.34 | H11: =+F11-G11 -> -1209.98 | I11: =G11/F11 -> 1.0199718 | J11: ='DRE 2026'!B8 -> 607970.16 | K11: ='DRE 2026'!C8 -> 62184.36 | L11: =C11 -> 62013.17 | M11: =K11-L11 -> 171.19 | N11: =L11/K11 -> 0.99724706 | O11: =J11-L11 -> 545956.99 | Q11: ='Base_Resultado Mensal_V2'!O58 -> 123807.51 | R11: =L11-Q11 -> -61794.34
A12: ='Base_Resultado Mensal_V2'!A75 -> Participação/comissão - Arbitragem | C12: ='Base_Resultado Mensal_V2'!C75+'Base_Resultado Mensal_V2'!C76 -> 0 | G12: ='Base_Resultado Mensal_V2'!D75+'Base_Resultado Mensal_V2'!D76 -> 0 | L12: =C12 -> 0 | Q12: ='Base_Resultado Mensal_V2'!O75+'Base_Resultado Mensal_V2'!O76 -> 0 | R12: =L12-Q12 -> 0
A13: Despesas Indiretas | B13: =SUM(B14:B24) -> 102906.66 | C13: =SUM(C14:C24) -> 104973.54 | D13: =(B13-C13) -> -2066.8767 | F13: =SUM(F14:F24) -> 100790.33 | G13: =SUM(G14:G24) -> 98454.78 | H13: =(F13-G13) -> 2335.5471 | J13: =SUM(J14:J24) -> 1331793.8 | K13: =SUM(K14:K24) -> 102906.66 | L13: =SUM(L14:L24) -> 104973.54 | M13: =K13-L13 -> -2066.8767 | N13: =L13/K13 -> 1.020085 | O13: =J13-L13 -> 1226820.3 | Q13: =SUM(Q14:Q24) -> 202043.58 | R13: =L13-Q13 -> -97070.04
A14: =+'Base_Resultado Mensal_V2'!A80 -> Ocupação | B14: ='DRE 2026'!C10 -> 27197.48 | C14: ='Base_Resultado Mensal_V2'!C80 -> 32337.05 | D14: =+B14-C14 -> -5139.57 | E14: =(C14/B14) -> 1.1889723 | F14: ='DRE 2026'!D10 -> 34236.38 | G14: ='Base_Resultado Mensal_V2'!D80 -> 39406.76 | H14: =+F14-G14 -> -5170.38 | I14: =(G14/F14) -> 1.1510201 | J14: ='DRE 2026'!B10 -> 410635.68 | K14: ='DRE 2026'!C10 -> 27197.48 | L14: =C14 -> 32337.05 | M14: =K14-L14 -> -5139.57 | N14: =L14/K14 -> 1.1889723 | O14: =J14-L14 -> 378298.63 | Q14: ='Base_Resultado Mensal_V2'!B80 -> 71743.81 | R14: =L14-Q14 -> -39406.76
A15: =+'Base_Resultado Mensal_V2'!A87 -> Telecomunicações | B15: ='DRE 2026'!C11 -> 890 | C15: ='Base_Resultado Mensal_V2'!C87 -> 807.16 | D15: =+B15-C15 -> 82.84 | E15: =(C15/B15) -> 0.90692135 | F15: ='DRE 2026'!D11 -> 839.7638 | G15: ='Base_Resultado Mensal_V2'!D87 -> 807.16 | H15: =+F15-G15 -> 32.6038 | I15: =(G15/F15) -> 0.96117504 | J15: ='DRE 2026'!B11 -> 10127.402 | K15: ='DRE 2026'!C11 -> 890 | L15: =C15 -> 807.16 | M15: =K15-L15 -> 82.84 | N15: =L15/K15 -> 0.90692135 | O15: =J15-L15 -> 9320.2418 | Q15: ='Base_Resultado Mensal_V2'!B87 -> 1614.32 | R15: =L15-Q15 -> -807.16
A16: =+'Base_Resultado Mensal_V2'!A90 -> Despesas Gerais | B16: ='DRE 2026'!C12 -> 7255 | C16: ='Base_Resultado Mensal_V2'!C90 -> 6773.44 | D16: =+B16-C16 -> 481.56 | E16: =(C16/B16) -> 0.93362371 | F16: ='DRE 2026'!D12 -> 5505 | G16: ='Base_Resultado Mensal_V2'!D90 -> 5243.68 | H16: =+F16-G16 -> 261.32 | I16: =(G16/F16) -> 0.95253043 | J16: ='DRE 2026'!B12 -> 74921.85 | K16: ='DRE 2026'!C12 -> 7255 | L16: =C16 -> 6773.44 | M16: =K16-L16 -> 481.56 | N16: =L16/K16 -> 0.93362371 | O16: =J16-L16 -> 68148.41 | Q16: ='Base_Resultado Mensal_V2'!B90 -> 12017.12 | R16: =L16-Q16 -> -5243.68
A17: =+'Base_Resultado Mensal_V2'!A105 -> Consultoria | B17: ='DRE 2026'!C13 -> 23240.8 | C17: ='Base_Resultado Mensal_V2'!C105 -> 30035.14 | D17: =+B17-C17 -> -6794.34 | E17: =(C17/B17) -> 1.2923454 | F17: ='DRE 2026'!D13 -> 23035.8 | G17: ='Base_Resultado Mensal_V2'!D105 -> 22509.85 | H17: =+F17-G17 -> 525.95 | I17: =(G17/F17) -> 0.97716815 | J17: ='DRE 2026'!B13 -> 244264.88 | K17: ='DRE 2026'!C13 -> 23240.8 | L17: =C17 -> 30035.14 | M17: =K17-L17 -> -6794.34 | N17: =L17/K17 -> 1.2923454 | O17: =J17-L17 -> 214229.74 | Q17: ='Base_Resultado Mensal_V2'!B105 -> 52544.99 | R17: =L17-Q17 -> -22509.85
A18: =+'Base_Resultado Mensal_V2'!A111 -> Salários Administração | B18: ='DRE 2026'!C14 -> 6426.58 | C18: ='Base_Resultado Mensal_V2'!C111 -> 5139.13 | D18: =+B18-C18 -> 1287.45 | E18: =(C18/B18) -> 0.79966794 | F18: ='DRE 2026'!D14 -> 6776.58 | G18: ='Base_Resultado Mensal_V2'!D111 -> 4807.3 | H18: =+F18-G18 -> 1969.28 | I18: =(G18/F18) -> 0.70939914 | J18: ='DRE 2026'!B14 -> 82659.531 | K18: ='DRE 2026'!C14 -> 6426.58 | L18: =C18 -> 5139.13 | M18: =K18-L18 -> 1287.45 | N18: =L18/K18 -> 0.79966794 | O18: =J18-L18 -> 77520.401 | Q18: ='Base_Resultado Mensal_V2'!B111 -> 9946.43 | R18: =L18-Q18 -> -4807.3
A19: =+'Base_Resultado Mensal_V2'!A119 -> Administrativas | B19: ='DRE 2026'!C15 -> 2996.8033 | C19: ='Base_Resultado Mensal_V2'!C119 -> 4300.03 | D19: =+B19-C19 -> -1303.2267 | E19: =(C19/B19) -> 1.4348723 | F19: ='DRE 2026'!D15 -> 2996.8033 | G19: ='Base_Resultado Mensal_V2'!D119 -> 6892.33 | H19: =+F19-G19 -> -3895.5267 | I19: =(G19/F19) -> 2.299894 | J19: ='DRE 2026'!B15 -> 91084.465 | K19: ='DRE 2026'!C15 -> 2996.8033 | L19: =C19 -> 4300.03 | M19: =K19-L19 -> -1303.2267 | N19: =L19/K19 -> 1.4348723 | O19: =J19-L19 -> 86784.435 | Q19: ='Base_Resultado Mensal_V2'!B119 -> 11192.36 | R19: =L19-Q19 -> -6892.33
A20: ='Base_Resultado Mensal_V2'!A129 -> Taxas / Despesas Financeiras | B20: ='DRE 2026'!C16 -> 0 | C20: ='Base_Resultado Mensal_V2'!C129 -> 0 | D20: =+B20-C20 -> 0 | F20: ='DRE 2026'!D16 -> 0 | G20: ='Base_Resultado Mensal_V2'!D129 -> 0 | H20: =+F20-G20 -> 0 | J20: ='DRE 2026'!B16 -> 0 | K20: ='DRE 2026'!C16 -> 0 | L20: =C20 -> 0 | M20: =K20-L20 -> 0 | O20: =J20-L20 -> 0 | Q20: ='Base_Resultado Mensal_V2'!B129 -> 0 | R20: =L20-Q20 -> 0
A21: =+'Base_Resultado Mensal_V2'!A132 -> Investimentos em Prospecção | B21: ='DRE 2026'!C17 -> 4500 | C21: ='Base_Resultado Mensal_V2'!C132 -> 2702.45 | D21: =+B21-C21 -> 1797.55 | E21: =(C21/B21) -> 0.60054444 | F21: ='DRE 2026'!D17 -> 4500 | G21: ='Base_Resultado Mensal_V2'!D132 -> 1166.75 | H21: =+F21-G21 -> 3333.25 | I21: =(G21/F21) -> 0.25927778 | J21: ='DRE 2026'!B17 -> 96000 | K21: ='DRE 2026'!C17 -> 4500 | L21: =C21 -> 2702.45 | M21: =K21-L21 -> 1797.55 | N21: =L21/K21 -> 0.60054444 | O21: =J21-L21 -> 93297.55 | Q21: ='Base_Resultado Mensal_V2'!B132 -> 2484.46 | R21: =L21-Q21 -> 217.99
A22: ='Base_Resultado Mensal_V2'!A159 -> Endomarketing | B22: ='DRE 2026'!C18 -> 100 | C22: ='Base_Resultado Mensal_V2'!C159 -> 0 | D22: =+B22-C22 -> 100 | E22: =(C22/B22) -> 0 | F22: ='DRE 2026'!D18 -> 100 | G22: ='Base_Resultado Mensal_V2'!D159 -> 0 | H22: =+F22-G22 -> 100 | I22: =(G22/F22) -> 0 | J22: ='DRE 2026'!B18 -> 1200 | K22: ='DRE 2026'!C18 -> 100 | L22: =C22 -> 0 | M22: =K22-L22 -> 100 | N22: =L22/K22 -> 0 | O22: =J22-L22 -> 1200 | Q22: ='Base_Resultado Mensal_V2'!B159 -> 0 | R22: =L22-Q22 -> 0
A23: ='Base_Resultado Mensal_V2'!A153 -> Gestão do Conhecimento | B23: ='DRE 2026'!C19 -> 0 | C23: ='Base_Resultado Mensal_V2'!C153 -> 692.37 | D23: =+B23-C23 -> -692.37 | F23: ='DRE 2026'!D19 -> 0 | G23: ='Base_Resultado Mensal_V2'!D153 -> 0 | H23: =+F23-G23 -> 0 | J23: ='DRE 2026'!B19 -> 2300 | K23: ='DRE 2026'!C19 -> 0 | L23: =C23 -> 692.37 | M23: =K23-L23 -> -692.37 | N23: =L23/K23 -> #DIV/0! | O23: =J23-L23 -> 1607.63 | Q23: ='Base_Resultado Mensal_V2'!B153 -> 692.37 | R23: =L23-Q23 -> 0
A24: =+'Base_Resultado Mensal_V2'!A175 -> Informática | B24: ='DRE 2026'!C20 -> 30300 | C24: ='Base_Resultado Mensal_V2'!C175 -> 22186.77 | D24: =+B24-C24 -> 8113.23 | E24: =(C24/B24) -> 0.73223663 | F24: ='DRE 2026'!D20 -> 22800 | G24: ='Base_Resultado Mensal_V2'!D175 -> 17620.95 | H24: =+F24-G24 -> 5179.05 | I24: =(G24/F24) -> 0.77284868 | J24: ='DRE 2026'!B20 -> 318600 | K24: ='DRE 2026'!C20 -> 30300 | L24: =C24 -> 22186.77 | M24: =K24-L24 -> 8113.23 | N24: =L24/K24 -> 0.73223663 | O24: =J24-L24 -> 296413.23 | Q24: ='Base_Resultado Mensal_V2'!B175 -> 39807.72 | R24: =L24-Q24 -> -17620.95
A25: Resultado Bruto | B25: =B3-B6-B13 -> 355342.42 | C25: =C4-C6-C13 -> -36782.99 | F25: =F3-F6-F13 -> 362158.75 | G25: =G4-G6-G13 -> 865.37 | J25: =J3-J6-J13 -> 4324323.6 | K25: =K3-K6-K13 -> 1027009.1 | L25: =L4-L6-L13 -> 282450.59 | Q25: =Q4-Q6-Q13 -> -34532.88
A26: Margem de bruta | B26: =B25/B3 -> 0.52904578 | C26: =C25/C4 -> -0.13145182 | F26: =F25/F3 -> 0.53919417 | G26: =G25/G4 -> 0.0027107737 | J26: =J25/J3 -> 0.53651657 | K26: =K25/K3 -> 0.76452289 | L26: =L25/L4 -> 0.47149386 | Q26: =Q25/Q4 -> -0.057645625
A27: 0.15
A28: Impostos | B28: ='DRE 2026'!C23 -> 150750 | C28: =C4*$A$27 -> 41973.16 | F28: ='DRE 2026'!D23 -> 150750 | G28: ='Base_Resultado Mensal_V2'!D163 -> 5641.82 | H28: =+F28-G28 -> 145108.18 | J28: ='DRE 2026'!B23 -> 1809000 | K28: ='DRE 2026'!C23 -> 150750 | L28: =C28 -> 41973.16 | R28: =L28-Q28 -> 41973.16
A29: Investimento amortização | B29: ='DRE 2026'!C24 -> 8117 | C29: 8117 | F29: 8117 | G29: =F29 -> 8117 | H29: =+F29-G29 -> 0 | J29: ='DRE 2026'!B24 -> 97404 | K29: ='DRE 2026'!C24 -> 8117 | L29: =C29 -> 8117 | R29: =L29-Q29 -> 8117
A30: Resultado Liquido após impostos | B30: =B25-B28-B29 -> 196475.42 | C30: =C25-C28-C29 -> -86873.151 | F30: =F25-F28-F29 -> 203291.75 | G30: =G25-G28-G29 -> -12893.45 | J30: =J25-J28-J29 -> 2417919.6 | K30: =K25-K28-K29 -> 868142.09 | L30: =L25-L28-L29 -> 232360.43 | R30: =L30-Q30 -> 232360.43
A31: Margem liquida | B31: =B30/B3 -> 0.29251923 | C31: =C30/C4 -> -0.31045965 | F31: =F30/F3 -> 0.30266762 | G31: =G30/G4 -> -0.040388765 | J31: =J30/J3 -> 0.29999002 | K31: =K30/K3 -> 0.64625961 | L31: =L30/L4 -> 0.38787852
A32: Bonus | B32: =B30*10% -> 19647.542 | C32: =C30*10% -> -8687.3151 | F32: =F30*10% -> 20329.175 | G32: =G30*10% -> -1289.345 | J32: =J30*10% -> 241791.96 | K32: =K30*10% -> 86814.209 | L32: =L30*10%-9.9 -> 23226.143 | R32: =L32-Q32 -> 23226.143
A34: 0.15 | B34: Janeiro | F34: Fevereiro
A35: Resultado Contencioso | B35: Orçado | C35: Realizado | D35: Variação Mensal | E35: Desvio% | F35: Orçado | G35: Realizado | H35: Variação Mensal | I35: Desvio% | J35: Orçado YTG | K35: Orçado YTD | L35: Realizado | M35: Variação | N35: Desvio% | O35: YTG
A36: Receita | B36: =($B$3-($B$3/4))/2 -> 251875 | C36: =57491+'Resumo_Recebidas 2025_2026'!M142+'Resumo_Recebidas 2025_2026'!O153 -> 72613.091 | D36: =C36-B36 -> -179261.91 | E36: =C36/B36 -> 0.28829018 | F36: =B36 -> 251875 | G36: =133203+'Resumo_Recebidas 2025_2026'!M144+'Resumo_Recebidas 2025_2026'!O155 -> 138600.13 | H36: =G36-F36 -> -113274.87 | I36: =G36/F36 -> 0.55027346 | J36: =($J$3-($J$3/4))/2 -> 3022500 | K36: =B36 -> 251875 | L36: =C36 -> 72613.091 | M36: =L36-K36 -> -179261.91 | N36: =L36/K36 -> 0.28829018 | O36: =J36-L36 -> 2949886.9 | Q36: =L36 -> 72613.091 | R36: =L36-Q36 -> 0
A38: Despesas | B38: Orçado | C38: Realizado | D38: Variação Mensal | E38: Desvio% | F38: Orçado | G38: Realizado | H38: Variação Mensal | I38: Desvio% | J38: Orçado YTG | K38: Orçado YTD | L38: Realizado | M38: Variação | N38: Desvio% | O38: YTG
A39: Custo Equipe | B39: =+B7 -> 74354.065 | C39: =+'Base_Resultado Mensal_V2'!C5 -> 73576.315 | D39: =+B39-C39 -> 777.75 | E39: =C39/B39 -> 0.98953991 | F39: =+F7 -> 72754.065 | G39: ='Base_Resultado Mensal_V2'!D5 -> 76342.345 | H39: =+F39-G39 -> -3588.28 | I39: =G39/F39 -> 1.0493207 | J39: ='Base_Resultado Mensal_V2'!B5 -> 149918.66 | K39: =B39 -> 74354.065 | L39: =C39 -> 73576.315 | M39: =K39-L39 -> 777.75 | N39: =L39/K39 -> 0.98953991 | O39: =J39-L39 -> 76342.345 | Q39: ='Base_Resultado Mensal_V2'!B5 -> 149918.66 | R39: =L39-Q39 -> -76342.345
A40: =A8 -> Participação/Comissão - Contencioso | C40: =C8 -> 0 | G40: ='Base_Resultado Mensal_V2'!D28 -> 0 | L40: =C40 -> 0 | Q40: =L40 -> 0
A41: Despesas Equipe | B41: ='Orçamento 2026'!D191 -> 2110.49 | C41: =+'Base_Resultado Mensal_V2'!C200 -> 1060.095 | D41: =(B41-C41) -> 1050.395 | E41: =C41/B41 -> 0.50229804 | F41: ='Orçamento 2026'!E191 -> 2110.49 | H41: =(F41-G41) -> 2110.49 | I41: =G41/F41 -> 0 | J41: ='Base_Resultado Mensal_V2'!B200 -> 3791.6483 | K41: =B41 -> 2110.49 | L41: =C41 -> 1060.095 | M41: =K41-L41 -> 1050.395 | N41: =L41/K41 -> 0.50229804 | O41: =J41-L41 -> 2731.5533 | Q41: ='Base_Resultado Mensal_V2'!O200 -> 3791.6483 | R41: =L41-Q41 -> -2731.5533
A42: Despesas Institucional | B42: =(B13-B41)*'Rateio Mensal'!M2 -> 36974.283 | C42: ='Rateio Mensal'!I2 -> 35425.447 | D42: =B42-C42 -> 1548.8363 | E42: =C42/B42 -> 0.95811044 | F42: =(F13-F41)*'Rateio Mensal'!M2 -> 36197.964 | H42: =F42-G42 -> 36197.964 | I42: =G42/F42 -> 0 | J42: =(J13-J21)*'Rateio Mensal'!M3 -> 469930.32 | K42: =B42 -> 36974.283 | L42: =C42 -> 35425.447 | M42: =K42-L42 -> 1548.8363 | N42: =L42/K42 -> 0.95811044 | O42: =J42-L42 -> 434504.88 | Q42: =L42 -> 35425.447 | R42: =L42-Q42 -> 0
...

Sheet Institucional
B1: Orçado | C1: Realizado
A2: Recebimento | B2: ='Areas Sintetico atualizado'!K3 -> 1343333.3 | C2: ='Areas Sintetico atualizado'!L4 -> 599054.65
A3: Custo equipe | B3: ='[1]Areas Sintetico atualizado'!AI7 -> 1806527.7 | C3: ='Areas Sintetico atualizado'!L6 -> 211630.52 | D3: =C3/$C$2 -> 0.35327415
A4: Despesas | B4: ='[1]Areas Sintetico atualizado'!AI11 -> 1228915.9 | C4: ='Areas Sintetico atualizado'!L13 -> 104973.54 | D4: =C4/$C$2 -> 0.17523199
A5: Resultado Bruto | B5: =B2-B3-B4 -> -1692110.3 | C5: =C2-C3-C4 -> 282450.59 | D5: =C5/$C$2 -> 0.47149386
A6: Imposto | B6: =B2*14.53% -> 195186.33 | C6: ='Areas Sintetico atualizado'!L28 -> 41973.16
A7: Amortização | C7: ='Areas Sintetico atualizado'!L29 -> 8117
A8: Resultado Liquido | B8: =B5-B6 -> -1887296.7 | C8: =C5-C6-C7 -> 232360.43
A11: Recebimento
A12: Custo equipe | C12: =D3 -> 0.35327415
A13: Despesas | C13: =D4 -> 0.17523199
A14: Resultado Bruto | C14: =D5 -> 0.47149386
A15: Imposto
A16: Resultado Liquido
A20: =A2 -> Recebimento | B20: =C2 -> 599054.65
A21: ='Areas Sintetico atualizado'!A14 -> Ocupação | B21: ='Areas Sintetico atualizado'!L14 -> 32337.05 | C21: =B21/$B$20 -> 0.053980134
A22: ='Areas Sintetico atualizado'!A15 -> Telecomunicações | B22: ='Areas Sintetico atualizado'!L15 -> 807.16 | C22: =B22/$B$20 -> 0.0013473896
A23: ='Areas Sintetico atualizado'!A16 -> Despesas Gerais | B23: ='Areas Sintetico atualizado'!L16 -> 6773.44 | C23: =B23/$B$20 -> 0.011306882
A24: ='Areas Sintetico atualizado'!A17 -> Consultoria | B24: ='Areas Sintetico atualizado'!L17 -> 30035.14 | C24: =B24/$B$20 -> 0.050137563
