Workbook
Name \0: #REF!
Name \a: #REF!
Name \b: #REF!
Name \c: #REF!
Name \d: #REF!
Name \df: #N/A
Name \e: #REF!
Name \f: #REF!
Name \i: #REF!
Name \l: #REF!
Name \PRINT_BALANCO: #REF!
Name \r: #REF!
Name \s: #REF!
Name \t: #REF!
Name _________________________________INV12: #REF!
Name _________________________________INV13: #REF!
Name _________________________________inv2: #REF!
Name _________________________________inv2: #REF!
Name _________________________________inv2: #REF!
Name ________________________________INV12: #REF!
Name ________________________________INV13: #REF!
Name ________________________________inv2: #REF!
Name ________________________________inv2: #REF!
Name ________________________________inv2: #REF!
Name _______________________________INV12: #REF!
Name _______________________________INV13: #REF!
Name _______________________________inv2: #REF!
Name _______________________________inv2: #REF!
Name _______________________________inv2: #REF!
Name ______________________________INV12: #REF!
Name ______________________________INV13: #REF!
Name ______________________________inv2: #REF!
Name ______________________________inv2: #REF!
Name ______________________________inv2: #REF!
Name _____________________________INV12: #REF!
Name _____________________________INV13: #REF!
Name _____________________________inv2: #REF!
Name _____________________________inv2: #REF!
Name _____________________________inv2: #REF!
Name ____________________________INV12: #REF!
Name ____________________________INV13: #REF!
Name ____________________________inv2: #REF!
Name ____________________________inv2: #REF!
Name ____________________________inv2: #REF!
Name ___________________________INV12: #REF!
Name ___________________________INV13: #REF!
Name ___________________________inv2: #REF!
Name ___________________________inv2: #REF!
Name ___________________________inv2: #REF!
Name __________________________INV12: #REF!
Name __________________________INV13: #REF!
Name __________________________inv2: #REF!
Name __________________________inv2: #REF!
Name __________________________inv2: #REF!
Name _________________________INV12: #REF!
Name _________________________INV13: #REF!
Name _________________________inv2: #REF!
Name _________________________inv2: #REF!
Name _________________________inv2: #REF!
Name ________________________INV12: #REF!

Sheet Meta (2)
A1: META 2026 | D1: YTD | H1: jan a jun | I1: jan a ago | J1: projeção ate dez
A2: Meta Anual | C2: 12 | D2: 1 | E2: 11 | F2: Nova meta mês | H2: 3120555 | I2: =D3 -> 444545.69 | J2: =I2+576522+85120+420000+374267+140000+(400000*3) -> 3240454.7 | L2: 576622 | M2: Nacionais
A3: 8060000 | C3: =A3/C2 -> 671666.67 | D3: ='Areas Sintetico atualizado'!C3 -> 444545.69 | E3: =A3-D3 -> 7615454.3 | F3: =E3/E2 -> 692314.03 | H3: =H2/A3 -> 0.38716563 | I3: =I2/A3 -> 0.055154552 | J3: =J2/A3 -> 0.40204152 | L3: 85120 | M3: Internacionais
L4: 420000 | M4: Pre faturas
I5: =10377407-5768380 -> 4609027 | L5: 374267 | M5: WM
I6: =(I2/I5)-1 -> -0.90354891 | L6: 140000 | M6: Tonico
A7: META 2025 | D7: YTD | J7: 6143091
A8: Meta Anual | C8: 12 | J8: =(J2/J7)-1 -> -0.4725042
A9: =A3 -> 8060000 | C9: =A9/C8 -> 671666.67 | D9: ='Areas Sintetico atualizado'!X3 -> 2372506.6 | F9: =A9-D9 -> 5687493.4 | G9: =F9/E2 -> 517044.85
B13: Faturamento | C13: Recebimento | D13: Faturamento | E13: Meta | F13: Despesas | G13: Despesas indiretas | H13: Custo direto
A14: Jan | B14: ='Areas Sintetico atualizado'!C3 -> 444545.69 | C14: ='Areas Sintetico atualizado'!C4 -> 279821.07 | D14: ='Areas Sintetico atualizado'!C3 -> 444545.69 | E14: 671667 | F14: =G14+H14 -> 311424.09 | G14: ='Areas Sintetico atualizado'!C13 -> 100181.41 | H14: ='Areas Sintetico atualizado'!C6 -> 211242.68 | J14: =C14-G14-H14 -> -31603.02
A15: Fev | B15: ='Areas Sintetico atualizado'!G3 -> 534752.84 | C15: ='Areas Sintetico atualizado'!G4 -> 319233.58 | E15: 671667 | F15: =G15+H15 -> 313501.13 | G15: ='Areas Sintetico atualizado'!G13 -> 95047.39 | H15: ='Areas Sintetico atualizado'!G6 -> 218453.74 | J15: =C15-G15-H15 -> 5732.45
A16: Mar | E16: 671667 | F16: =G16+H16 -> 0 | J16: =C16-G16-H16 -> 0
A17: Abr | E17: 671667 | F17: =G17+H17 -> 0 | J17: =C17-G17-H17 -> 0
A18: Mai | E18: 671667 | F18: =G18+H18 -> 0 | J18: =C18-G18-H18 -> 0
A19: Jun | E19: 671667 | F19: =G19+H19 -> 0 | J19: =C19-G19-H19 -> 0
A20: Jul | E20: 671667 | F20: =G20+H20 -> 0 | J20: =C20-G20-H20 -> 0
A21: Ago | E21: 671667 | F21: =G21+H21 -> 0 | J21: =C21-G21-H21 -> 0
A22: Set | E22: 671667 | F22: =G22+H22 -> 0 | J22: =C22-G22-H22 -> 0
A23: Out | E23: 671667 | F23: =G23+H23 -> 0 | J23: =C23-G23-H23 -> 0
A24: Nov | E24: 671667 | F24: =G24+H24 -> 0 | J24: =C24-G24-H24 -> 0
A25: Dez | E25: 671667 | F25: =G25+H25 -> 0 | J25: =C25-G25-H25 -> 0
C26: =SUM(C14:C25) -> 599054.65 | D26: =SUM(D14:D25) -> 444545.69 | E26: =SUM(E14:E25) -> 8060004 | F26: =SUM(F14:F25) -> 624925.22 | G26: =SUM(G14:G25) -> 195228.8 | H26: =SUM(H14:H25) -> 429696.42 | I26: =SUM(I14:I25) -> 0 | J26: =SUM(J14:J25) -> -25870.57
A28: MÉDIA ANUAL | C28: =C26/12 -> 49921.221
E31: =D26-G26-H26 -> -180379.53 | F31: =C26-G26-H26 -> -25870.57
C35: Recebimento | D35: Despesas | F35: #
A36: Jan | C36: 316807.42 | D36: 330244.38 | E36: ='[1]Base_Resultado Mensal_V2'!D190 -> 134911.6 | F36: =C36-D36-E36 -> -148348.56
A37: Fev | C37: 216057.27 | D37: 377306.7 | E37: ='[1]Base_Resultado Mensal_V2'!F190 -> 5092.45 | F37: =C37-D37-E37 -> -166341.88
A38: Mar | C38: 613202.96 | D38: 363984.21 | E38: ='[1]Base_Resultado Mensal_V2'!H190 -> 814.99 | F38: =C38-D38-E38 -> 248403.76
A39: Abr | C39: 588260.32 | D39: 375072.46 | E39: ='[1]Base_Resultado Mensal_V2'!J190 -> 110831.76 | F39: =C39-D39-E39 -> 102356.1
A40: Mai | C40: 658171.05 | D40: 360112.8 | E40: ='[1]Base_Resultado Mensal_V2'!L190 -> 5968 | F40: =C40-D40-E40 -> 292090.25
A41: Jun | C41: 632809.49 | D41: 334821.86 | E41: ='[1]Base_Resultado Mensal_V2'!N190 -> 11928.17 | F41: =C41-D41-E41 -> 286059.46
A42: Jul | C42: 260036.93 | D42: 337422.56 | E42: ='[1]Base_Resultado Mensal_V2'!P190 -> 183171.96 | F42: =C42-D42-E42 -> -260557.59
C43: 3285345.4 | D43: 2478965 | E43: =SUM(E36:E42) -> 452718.93

Sheet DRE 2026
A1: DRE | C1: Janeiro | D1: Fevereiro | E1: Março | F1: Abril | G1: Maio | H1: Junho | I1: Julho | J1: Agosto | K1: Setembro | L1: Outubro | M1: Novembro | N1: Dezembro
A2: Resultado Institucional | C2: Orçado | D2: Orçado | E2: Orçado | F2: Orçado | G2: Orçado | H2: Orçado | I2: Orçado | J2: Orçado | K2: Orçado | L2: Orçado | M2: Orçado | N2: Orçado
A3: Faturamento | B3: =SUM(C3:N3) -> 8060000 | C3: 671666.67 | D3: 671666.67 | E3: 671666.67 | F3: 671666.67 | G3: 671666.67 | H3: 671666.67 | I3: 671666.67 | J3: 671666.67 | K3: 671666.67 | L3: 671666.67 | M3: 671666.67 | N3: 671666.67
A4: Despesas
A5: Custos Diretos | B5: =SUM(C5:N5) -> 2438910.6 | C5: =SUM(C6:C8) -> 215786.59 | D5: =SUM(D6:D8) -> 211686.59 | E5: =SUM(E6:E8) -> 199069.61 | F5: =SUM(F6:F8) -> 203869.61 | G5: =SUM(G6:G8) -> 199069.61 | H5: =SUM(H6:H8) -> 199069.61 | I5: =SUM(I6:I8) -> 203869.61 | J5: =SUM(J6:J8) -> 199069.61 | ... N5: =SUM(N6:N8) -> 201097.67
A6: Custo equipe - Contencioso | B6: =SUM(C6:N6) -> 901597.73 | C6: ='[2]Orçamento 2026'!D5 -> 75454.065 | D6: ='[2]Orçamento 2026'!E5 -> 74454.065 | E6: ='[2]Orçamento 2026'!F5 -> 74454.065 | F6: ='[2]Orçamento 2026'!G5 -> 76054.065 | G6: ='[2]Orçamento 2026'!H5 -> 74454.065 | H6: ='[2]Orçamento 2026'!I5 -> 74454.065 | I6: ='[2]Orçamento 2026'!J5 -> 76054.065 | J6: ='[2]Orçamento 2026'!K5 -> 74454.065 | ... N6: ='[2]Orçamento 2026'!O5 -> 75151.317
A7: Custo equipe - Econômico | B7: =SUM(C7:N7) -> 914114.75 | C7: ='[2]Orçamento 2026'!D28 -> 76879.165 | D7: ='[2]Orçamento 2026'!E28 -> 75379.165 | E7: ='[2]Orçamento 2026'!F28 -> 75379.165 | F7: ='[2]Orçamento 2026'!G28 -> 76979.165 | G7: ='[2]Orçamento 2026'!H28 -> 75379.165 | H7: ='[2]Orçamento 2026'!I28 -> 75379.165 | I7: ='[2]Orçamento 2026'!J28 -> 76979.165 | J7: ='[2]Orçamento 2026'!K28 -> 75379.165 | ... N7: ='[2]Orçamento 2026'!O28 -> 76467.423
A8: Custo equipe - Arbitragem e Compliance | B8: =SUM(C8:N8) -> 623198.16 | C8: ='[2]Orçamento 2026'!D53 -> 63453.36 | D8: ='[2]Orçamento 2026'!E53 -> 61853.36 | E8: ='[2]Orçamento 2026'!F53 -> 49236.38 | F8: ='[2]Orçamento 2026'!G53 -> 50836.38 | G8: ='[2]Orçamento 2026'!H53 -> 49236.38 | H8: ='[2]Orçamento 2026'!I53 -> 49236.38 | I8: ='[2]Orçamento 2026'!J53 -> 50836.38 | J8: ='[2]Orçamento 2026'!K53 -> 49236.38 | ... N8: ='[2]Orçamento 2026'!O53 -> 49478.927
A9: Despesas Indiretas | B9: =SUM(C9:N9) -> 1386633.4 | C9: =SUM(C10:C20) -> 102906.66 | D9: =SUM(D10:D20) -> 112483.91 | E9: =SUM(E10:E20) -> 129851.12 | F9: =SUM(F10:F20) -> 124351.12 | G9: =SUM(G10:G20) -> 103162.07 | H9: =SUM(H10:H20) -> 106230.33 | I9: =SUM(I10:I20) -> 114809.44 | J9: =SUM(J10:J20) -> 108120.57 | ... N9: =SUM(N10:N20) -> 142584.19
A10: Ocupação | B10: =SUM(C10:N10) -> 410635.68 | C10: ='[2]Orçamento 2026'!D74 -> 27197.48 | D10: ='[2]Orçamento 2026'!E74 -> 34236.38 | E10: ='[2]Orçamento 2026'!F74 -> 34236.38 | F10: ='[2]Orçamento 2026'!G74 -> 34236.38 | G10: ='[2]Orçamento 2026'!H74 -> 34236.38 | H10: ='[2]Orçamento 2026'!I74 -> 35213.24 | I10: ='[2]Orçamento 2026'!J74 -> 35213.24 | J10: ='[2]Orçamento 2026'!K74 -> 35213.24 | ... N10: ='[2]Orçamento 2026'!O74 -> 35213.24
A11: Telecomunicações | B11: =SUM(C11:N11) -> 10127.402 | C11: ='[2]Orçamento 2026'!D81 -> 890 | D11: ='[2]Orçamento 2026'!E81 -> 839.7638 | E11: ='[2]Orçamento 2026'!F81 -> 839.7638 | F11: ='[2]Orçamento 2026'!G81 -> 839.7638 | G11: ='[2]Orçamento 2026'!H81 -> 839.7638 | H11: ='[2]Orçamento 2026'!I81 -> 839.7638 | I11: ='[2]Orçamento 2026'!J81 -> 839.7638 | J11: ='[2]Orçamento 2026'!K81 -> 839.7638 | ... N11: ='[2]Orçamento 2026'!O81 -> 839.7638
A12: Despesas Gerais | B12: =SUM(C12:N12) -> 74921.85 | C12: ='[2]Orçamento 2026'!D84 -> 7255 | D12: ='[2]Orçamento 2026'!E84 -> 5505 | E12: ='[2]Orçamento 2026'!F84 -> 5742.205 | F12: ='[2]Orçamento 2026'!G84 -> 7292.205 | G12: ='[2]Orçamento 2026'!H84 -> 5742.205 | H12: ='[2]Orçamento 2026'!I84 -> 5683.605 | I12: ='[2]Orçamento 2026'!J84 -> 7333.605 | J12: ='[2]Orçamento 2026'!K84 -> 5683.605 | ... N12: ='[2]Orçamento 2026'!O84 -> 5783.605
A13: Consultoria | B13: =SUM(C13:N13) -> 287104.88 | C13: ='Orçamento 2026'!D98 -> 23240.8 | D13: ='Orçamento 2026'!E98 -> 23035.8 | E13: ='Orçamento 2026'!F98 -> 22815.8 | F13: ='Orçamento 2026'!G98 -> 23115.8 | G13: ='Orçamento 2026'!H98 -> 22815.8 | H13: ='Orçamento 2026'!I98 -> 23465.8 | I13: ='Orçamento 2026'!J98 -> 23240.8 | J13: ='Orçamento 2026'!K98 -> 24015.8 | ... N13: ='Orçamento 2026'!O98 -> 27532.561
A14: Salários Administração | B14: =SUM(C14:N14) -> 94659.531 | C14: ='[2]Orçamento 2026'!D104 -> 6426.58 | D14: ='[2]Orçamento 2026'!E104 -> 6776.58 | E14: ='Orçamento 2026'!F104 -> 7626.58 | F14: ='Orçamento 2026'!G104 -> 7626.58 | G14: ='Orçamento 2026'!H104 -> 7626.58 | H14: ='Orçamento 2026'!I104 -> 7626.58 | I14: ='Orçamento 2026'!J104 -> 7626.58 | J14: ='Orçamento 2026'!K104 -> 7626.58 | K14: ='Orçamento 2026'!L104 -> 7626.58 | L14: ='Orçamento 2026'!M104 -> 7823.437 | ... N14: ='Orçamento 2026'!O104 -> 10123.437
A15: Administrativas | B15: =SUM(C15:N15) -> 91084.049 | C15: ='[2]Orçamento 2026'!D112 -> 2996.8033 | D15: ='[2]Orçamento 2026'!E112 -> 14690.387 | E15: ='[2]Orçamento 2026'!F112 -> 14690.387 | F15: ='[2]Orçamento 2026'!G112 -> 14690.387 | G15: ='[2]Orçamento 2026'!H112 -> 3001.3367 | H15: ='[2]Orçamento 2026'!I112 -> 3001.3367 | I15: ='[2]Orçamento 2026'!J112 -> 5655.4486 | J15: ='[2]Orçamento 2026'!K112 -> 5691.5827 | ... N15: ='[2]Orçamento 2026'!O112 -> 5691.5827
A16: Taxas / Despesas Financeiras | B16: =SUM(C16:N16) -> 0
A17: Investimentos em Prospecção | B17: =SUM(C17:N17) -> 96000 | C17: ='[2]Orçamento 2026'!D125 -> 4500 | D17: ='[2]Orçamento 2026'!E125 -> 4500 | E17: ='[2]Orçamento 2026'!F125 -> 6000 | F17: ='[2]Orçamento 2026'!G125 -> 6000 | G17: ='[2]Orçamento 2026'!H125 -> 6000 | H17: ='[2]Orçamento 2026'!I125 -> 7500 | I17: ='[2]Orçamento 2026'!J125 -> 4500 | J17: ='[2]Orçamento 2026'!K125 -> 6000 | ... N17: ='[2]Orçamento 2026'!O125 -> 34500
A18: Endomarketing | B18: =SUM(C18:N18) -> 1200 | C18: ='[2]Orçamento 2026'!D152 -> 100 | D18: ='[2]Orçamento 2026'!E152 -> 100 | E18: ='[2]Orçamento 2026'!F152 -> 100 | F18: ='[2]Orçamento 2026'!G152 -> 100 | G18: ='[2]Orçamento 2026'!H152 -> 100 | H18: ='[2]Orçamento 2026'!I152 -> 100 | I18: ='[2]Orçamento 2026'!J152 -> 100 | J18: ='[2]Orçamento 2026'!K152 -> 100 | ... N18: ='[2]Orçamento 2026'!O152 -> 100
A19: ='[3]Areas Sintetico atualizado'!A21 -> Gestão do Conhecimento | B19: =SUM(C19:N19) -> 2300 | C19: ='[2]Orçamento 2026'!D146 -> 0 | D19: ='[2]Orçamento 2026'!E146 -> 0 | E19: ='[2]Orçamento 2026'!F146 -> 0 | F19: ='[2]Orçamento 2026'!G146 -> 150 | G19: ='[2]Orçamento 2026'!H146 -> 0 | H19: ='[2]Orçamento 2026'!I146 -> 0 | I19: ='[2]Orçamento 2026'!J146 -> 0 | J19: ='[2]Orçamento 2026'!K146 -> 150 | ... N19: ='[2]Orçamento 2026'!O146 -> 0
A20: Informática | B20: =SUM(C20:N20) -> 318600 | C20: ='[2]Orçamento 2026'!D162 -> 30300 | D20: ='[2]Orçamento 2026'!E162 -> 22800 | E20: ='[2]Orçamento 2026'!F162 -> 37800 | F20: ='[2]Orçamento 2026'!G162 -> 30300 | G20: ='[2]Orçamento 2026'!H162 -> 22800 | H20: ='[2]Orçamento 2026'!I162 -> 22800 | I20: ='[2]Orçamento 2026'!J162 -> 30300 | J20: ='[2]Orçamento 2026'!K162 -> 22800 | ... N20: ='[2]Orçamento 2026'!O162 -> 22800
A21: Resultado Bruto | B21: =B3-B5-B9 -> 4234456 | C21: =C3-C5-C9 -> 352973.42 | D21: =D3-D5-D9 -> 347496.17 | E21: =E3-E5-E9 -> 342745.94 | F21: =F3-F5-F9 -> 343445.94 | G21: =G3-G5-G9 -> 369434.99 | H21: =H3-H5-H9 -> 366366.73 | I21: =I3-I5-I9 -> 352987.62 | ... N21: =N3-N5-N9 -> 327984.81
A22: Margem de bruta | B22: =B21/B3 -> 0.52536675 | C22: =C21/C3 -> 0.52551873 | D22: =D21/D3 -> 0.51736402 | E22: =E21/E3 -> 0.51029173 | F22: =F21/F3 -> 0.51133391 | G22: =G21/G3 -> 0.55002728 | H22: =H21/H3 -> 0.54545916 | I22: =I21/I3 -> 0.52553988 | ... N22: =N21/N3 -> 0.48831486
A23: Impostos | B23: =C23+D23+E23+F23+G23+H23+I23+J23+K23+L23+M23+N23 -> 1209000 | C23: =(C3*15%) -> 100750 | D23: =(D3*15%) -> 100750 | E23: =(E3*15%) -> 100750 | F23: =(F3*15%) -> 100750 | G23: =(G3*15%) -> 100750 | H23: =(H3*15%) -> 100750 | I23: =(I3*15%) -> 100750 | J23: =(J3*15%) -> 100750 | ... N23: =(N3*15%) -> 100750
A24: Amortização | B24: =SUM(C24:N24) -> 97404 | C24: 8117 | D24: 8117 | E24: 8117 | F24: 8117 | G24: 8117 | H24: 8117 | I24: 8117 | J24: 8117 | K24: 8117 | L24: 8117 | M24: 8117 | N24: 8117
A25: Resultado Liquido após impostos | B25: =B21-B23-B24 -> 2928052 | C25: =C21-C23-C24 -> 244106.42 | D25: =D21-D23-D24 -> 238629.17 | E25: =E21-E23-E24 -> 233878.94 | F25: =F21-F23-F24 -> 234578.94 | G25: =G21-G23-G24 -> 260567.99 | H25: =H21-H23-H24 -> 257499.73 | I25: =I21-I23-I24 -> 244120.62 | ... N25: =N21-N23-N24 -> 219117.81
A26: Margem liquida | B26: =B25/B3 -> 0.36328188 | C26: =C25/C3 -> 0.36343387 | D26: =D25/D3 -> 0.35527916 | E26: =E25/E3 -> 0.34820686 | F26: =F25/F3 -> 0.34924905 | G26: =G25/G3 -> 0.38794242 | H26: =H25/H3 -> 0.38337429 | I26: =I25/I3 -> 0.36345502 | ... N26: =N25/N3 -> 0.32622999
A27: Reserva bônus | B27: =B25*10% -> 292805.2 | C27: =C25*10% -> 24410.642 | D27: =D25*10% -> 23862.917 | E27: =E25*10% -> 23387.894 | F27: =F25*10% -> 23457.894 | G27: =G25*10% -> 26056.799 | H27: =H25*10% -> 25749.973 | I27: =I25*10% -> 24412.062 | ... N27: =N25*10% -> 21911.781
B96: =SUM(B97:B102) -> 0 | D96: =SUM(D97:D102) -> 0 | E96: =SUM(E97:E102) -> 0 | F96: =SUM(F97:F102) -> 0 | G96: =SUM(G97:G102) -> 0 | H96: =SUM(H97:H102) -> 0 | I96: =SUM(I97:I102) -> 0 | J96: =SUM(J97:J102) -> 0 | K96: =SUM(K97:K102) -> 0 | ... N96: =SUM(N97:N102) -> 0
A103: Assinaturas
B137: =SUM(B138:B141) -> 0 | D137: =SUM(D138:D141) -> 0 | E137: =SUM(E138:E141) -> 0 | F137: =SUM(F138:F141) -> 0 | G137: =SUM(G138:G141) -> 0 | H137: =SUM(H138:H141) -> 0 | I137: =SUM(I138:I141) -> 0 | J137: =SUM(J138:J141) -> 0 | K137: =SUM(K138:K141) -> 0 | ... N137: =SUM(N138:N141) -> 0
B168: =B4+B26+B51+B67+B73+B76+B90+B96+B103+B142+B152+B116+B137 -> 0.36328188 | D168: =D4+D26+D51+D67+D73+D76+D90+D96+D103+D142+D152+D116+D137 -> 0.35527916 | E168: =E4+E26+E51+E67+E73+E76+E90+E96+E103+E142+E152+E116+E137 -> 0.34820686 | F168: =F4+F26+F51+F67+F73+F76+F90+F96+F103+F142+F152+F116+F137 -> 0.34924905 | G168: =G4+G26+G51+G67+G73+G76+G90+G96+G103+G142+G152+G116+G137 -> 0.38794242 | H168: =H4+H26+H51+H67+H73+H76+H90+H96+H103+H142+H152+H116+H137 -> 0.38337429 | I168: =I4+I26+I51+I67+I73+I76+I90+I96+I103+I142+I152+I116+I137 -> 0.36345502 | J168: =J4+J26+J51+J67+J73+J76+J90+J96+J103+J142+J152+J116+J137 -> 0.38056003 | K168: =K4+K26+K51+K67+K73+K76+K90+K96+K103+K142+K152+K116+K137 -> 0.38242107 | ... N168: =N4+N26+N51+N67+N73+N76+N90+N96+N103+N142+N152+N116+N137 -> 0.32622999

Sheet Orçamento 2026
C1: 0.045
A2: Resultado Financeiro 2026 | B2: Soma JAN. a DEZ. | D2: Janeiro | E2: Fevereiro | F2: Março | G2: Abril | H2: Maio | I2: Junho | J2: Julho | K2: Agosto | L2: Setembro | M2: Outubro | N2: Novembro | O2: Dezembro
A3: Movimentação de Entradas | B3: =SUM(C3:O3) -> 8060000 | D3: 671666.67 | E3: 671666.67 | F3: 671666.67 | G3: 671666.67 | H3: 671666.67 | I3: 671666.67 | J3: 671666.67 | K3: 671666.67 | L3: 671666.67 | M3: 671666.67 | N3: 671666.67 | O3: 671666.67
A4: Receita de honorários | B4: =SUM(D4:O4) -> 0
A5: Custo equipe - Contencioso | B5: =SUM(D5:O5) -> 901597.73 | D5: =SUM(D6:D27) -> 75454.065 | E5: =SUM(E6:E27) -> 74454.065 | F5: =SUM(F6:F27) -> 74454.065 | G5: =SUM(G6:G27) -> 76054.065 | H5: =SUM(H6:H27) -> 74454.065 | I5: =SUM(I6:I27) -> 74454.065 | J5: =SUM(J6:J27) -> 76054.065 | K5: =SUM(K6:K27) -> 74454.065 | ... O5: =SUM(O6:O27) -> 75151.317
A6: Daniel Costa Caselta - Distribuição Mensal Fixa | B6: =SUM(D6:O6) -> 280548 | D6: ='[2]Tabela 2025 2026'!Q13 -> 23379 | E6: =D6 -> 23379 | F6: =E6 -> 23379 | G6: =F6 -> 23379 | H6: =G6 -> 23379 | I6: =H6 -> 23379 | J6: =I6 -> 23379 | K6: =J6 -> 23379 | L6: =K6 -> 23379 | ... O6: =N6 -> 23379
A7: Daniel Costa Caselta - Pro labore | B7: =SUM(D7:O7) -> 19452 | D7: ='[2]Tabela 2025 2026'!M14 -> 1621 | E7: =D7 -> 1621 | F7: =E7 -> 1621 | G7: =F7 -> 1621 | H7: =G7 -> 1621 | I7: =H7 -> 1621 | J7: =I7 -> 1621 | K7: =J7 -> 1621 | L7: =K7 -> 1621 | ... O7: =N7 -> 1621
A8: Daniel Costa Caselta - Convenio Medico | B8: =SUM(D8:O8) -> 21825.998 | D8: 1794.65 | E8: =D8 -> 1794.65 | F8: =E8 -> 1794.65 | G8: =F8 -> 1794.65 | H8: =G8 -> 1794.65 | I8: =H8 -> 1794.65 | J8: =I8 -> 1794.65 | K8: =J8 -> 1794.65 | L8: =K8 -> 1794.65 | M8: =L8+(L8*[2]Premissas!B4) -> 2063.8475 | N8: 1804.65 | O8: 1805.65
A9: Aurelio Marchini Santos - Distribuição Mensal Fixa | B9: =SUM(D9:O9) -> 140274 | D9: ='[2]Tabela 2025 2026'!Q13/2 -> 11689.5 | E9: =D9 -> 11689.5 | F9: =E9 -> 11689.5 | G9: =F9 -> 11689.5 | H9: =G9 -> 11689.5 | I9: =H9 -> 11689.5 | J9: =I9 -> 11689.5 | K9: =J9 -> 11689.5 | L9: =K9 -> 11689.5 | ... O9: =N9 -> 11689.5
A10: Aurelio Marchini Santos- Pro labore | B10: =SUM(D10:O10) -> 9726 | D10: ='[2]Tabela 2025 2026'!M13/2 -> 810.5 | E10: =D10 -> 810.5 | F10: =E10 -> 810.5 | G10: =F10 -> 810.5 | H10: =G10 -> 810.5 | I10: =H10 -> 810.5 | J10: =I10 -> 810.5 | K10: =J10 -> 810.5 | L10: =K10 -> 810.5 | ... O10: =N10 -> 810.5
A11: Aurelio Marchini Santos - Convenio Medico | B11: =SUM(D11:O11) -> 20483.176 | D11: =(3290.47/2) -> 1645.235 | E11: =D11 -> 1645.235 | F11: =E11 -> 1645.235 | G11: =F11 -> 1645.235 | H11: =G11 -> 1645.235 | I11: =H11 -> 1645.235 | J11: =I11 -> 1645.235 | K11: =J11 -> 1645.235 | L11: =K11 -> 1645.235 | M11: =(3290.47/2)*[2]Premissas!B4+'Orçamento 2026'!L11 -> 1892.0202 | N11: =M11 -> 1892.0202 | O11: =N11 -> 1892.0202
A12: Beatriz Baes Xavier - Distribuição Mensal Fixa | B12: =SUM(D12:O12) -> 90448.8 | D12: ='[2]Tabela 2025 2026'!Q4 -> 7537.4 | E12: =D12 -> 7537.4 | F12: =E12 -> 7537.4 | G12: =F12 -> 7537.4 | H12: =G12 -> 7537.4 | I12: =H12 -> 7537.4 | J12: =I12 -> 7537.4 | K12: =J12 -> 7537.4 | L12: =K12 -> 7537.4 | ... O12: =N12 -> 7537.4
A13: Beatriz Baes Xavier - Pro Labore | B13: =SUM(D13:O13) -> 19452 | D13: ='[2]Tabela 2025 2026'!M4 -> 1621 | E13: =D13 -> 1621 | F13: =E13 -> 1621 | G13: =F13 -> 1621 | H13: =G13 -> 1621 | I13: =H13 -> 1621 | J13: =I13 -> 1621 | K13: =J13 -> 1621 | L13: =K13 -> 1621 | ... O13: =N13 -> 1621
A14: Beatriz Baes Xavier - Convenio Medico | B14: =SUM(D14:O14) -> 16344.36 | D14: 1312.8 | E14: =D14 -> 1312.8 | F14: =E14 -> 1312.8 | G14: =F14 -> 1312.8 | H14: =G14 -> 1312.8 | I14: =H14 -> 1312.8 | J14: =I14 -> 1312.8 | K14: =J14 -> 1312.8 | L14: =K14 -> 1312.8 | M14: =1312.8*[2]Premissas!B4+'Orçamento 2026'!L14 -> 1509.72 | N14: =M14 -> 1509.72 | O14: =N14 -> 1509.72
A15: Beatriz Baes Xavier - Despesas Extras - Cartao Predio | B15: =SUM(D15:O15) -> 0
A16: Beatriz Baes Xavier - Reajuste de Distribuição Mensal Fixa | B16: =SUM(D16:O16) -> 0
A17: Isabel de Almeida Rego Campinho - Distribuição Mensal Fixa | B17: =SUM(D17:O17) -> 187260 | D17: ='[2]Tabela 2025 2026'!Q9 -> 15605 | E17: =D17 -> 15605 | F17: =E17 -> 15605 | G17: =F17 -> 15605 | H17: =G17 -> 15605 | I17: =H17 -> 15605 | J17: =I17 -> 15605 | K17: =J17 -> 15605 | L17: =K17 -> 15605 | ... O17: =N17 -> 15605
A18: Isabel de Almeida Rego Campinho - Pro Labore | B18: =SUM(D18:O18) -> 19452 | D18: ='[2]Tabela 2025 2026'!M9 -> 1621 | E18: =D18 -> 1621 | F18: =E18 -> 1621 | G18: =F18 -> 1621 | H18: =G18 -> 1621 | I18: =H18 -> 1621 | J18: =I18 -> 1621 | K18: =J18 -> 1621 | L18: =K18 -> 1621 | ... O18: =N18 -> 1621
A19: Isabel de Almeida Rego Campinho - Convenio Medico | B19: =SUM(D19:O19) -> 20131.401 | D19: 1616.98 | E19: 1616.98 | F19: 1616.98 | G19: 1616.98 | H19: 1616.98 | I19: 1616.98 | J19: 1616.98 | K19: 1616.98 | L19: 1616.98 | M19: =1616.98*[2]Premissas!B4+'Orçamento 2026'!L19 -> 1859.527 | N19: =M19 -> 1859.527 | O19: =N19 -> 1859.527
A20: Isabel de Almeida Rego Campinho - Reajuste de Distribuição Mensal Fixa | B20: =SUM(D20:O20) -> 0
A21: Joao Victor estagiario | B21: =SUM(D21:O21) -> 33000 | D21: 2200 | E21: 2800 | F21: 2800 | G21: 2800 | H21: 2800 | I21: 2800 | J21: 2800 | K21: 2800 | L21: 2800 | M21: 2800 | N21: 2800 | O21: 2800
A22: Joao Victor VT | B22: =SUM(D22:O22) -> 3600 | D22: 300 | E22: 300 | F22: 300 | G22: 300 | H22: 300 | I22: 300 | J22: 300 | K22: 300 | L22: 300 | M22: 300 | N22: 300 | O22: 300
A23: ISS Trimestral | B23: =SUM(D23:O23) -> 6400 | D23: 1600 | G23: 1600 | J23: 1600 | M23: 1600
A24: Seguro de vida | B24: =SUM(D24:O24) -> 0
A25: Vale Refeição | B25: =SUM(D25:O25) -> 13200 | D25: 1100 | E25: 1100 | F25: 1100 | G25: 1100 | H25: 1100 | I25: 1100 | J25: 1100 | K25: 1100 | L25: 1100 | M25: 1100 | N25: 1100 | O25: 1100
A26: Amortização | B26: =SUM(D26:O26) -> 0
A27: Participação/comissão/repasse - Contencioso | B27: =SUM(D27:O27) -> 0
A28: Custo equipe - Econômico | B28: =SUM(D28:O28) -> 914114.75 | D28: =SUM(D29:D51) -> 76879.165 | E28: =SUM(E29:E51) -> 75379.165 | F28: =SUM(F29:F51) -> 75379.165 | G28: =SUM(G29:G51) -> 76979.165 | H28: =SUM(H29:H51) -> 75379.165 | I28: =SUM(I29:I51) -> 75379.165 | J28: =SUM(J29:J51) -> 76979.165 | K28: =SUM(K29:K51) -> 75379.165 | ... O28: =SUM(O29:O51) -> 76467.423
A29: Ricardo Franco Botelho - Distribuição Mensal Fixa | B29: =SUM(D29:O29) -> 280548 | D29: ='[2]Tabela 2025 2026'!Q16 -> 23379 | E29: =D29 -> 23379 | F29: =E29 -> 23379 | G29: =F29 -> 23379 | H29: =G29 -> 23379 | I29: =H29 -> 23379 | J29: =I29 -> 23379 | K29: =J29 -> 23379 | L29: =K29 -> 23379 | ... O29: =N29 -> 23379
A30: Ricardo Franco Botelho - Pro labore | B30: =SUM(D30:O30) -> 19452 | D30: ='[2]Tabela 2025 2026'!M16 -> 1621 | E30: =D30 -> 1621 | F30: =E30 -> 1621 | G30: =F30 -> 1621 | H30: =G30 -> 1621 | I30: =H30 -> 1621 | J30: =I30 -> 1621 | K30: =J30 -> 1621 | L30: =K30 -> 1621 | ... O30: =N30 -> 1621
A31: Ricardo Franco Botelho - Convenio Medico | B31: =SUM(D31:O31) -> 30320.481 | D31: 2435.38 | E31: 2435.38 | F31: 2435.38 | G31: 2435.38 | H31: 2435.38 | I31: 2435.38 | J31: 2435.38 | K31: 2435.38 | L31: 2435.38 | M31: =2435.38*[2]Premissas!B4+'Orçamento 2026'!L31 -> 2800.687 | N31: =M31 -> 2800.687 | O31: =N31 -> 2800.687
A32: Aurelio Marchini Santos - Distribuição Mensal Fixa | B32: =SUM(D32:O32) -> 140274 | D32: ='[2]Tabela 2025 2026'!Q13/2 -> 11689.5 | E32: =D32 -> 11689.5 | F32: =E32 -> 11689.5 | G32: =F32 -> 11689.5 | H32: =G32 -> 11689.5 | I32: =H32 -> 11689.5 | J32: =I32 -> 11689.5 | K32: =J32 -> 11689.5 | L32: =K32 -> 11689.5 | ... O32: =N32 -> 11689.5
A33: Aurelio Marchini Santos- Pro labore | B33: =SUM(D33:O33) -> 9726 | D33: ='[2]Tabela 2025 2026'!M13/2 -> 810.5 | E33: =D33 -> 810.5 | F33: =E33 -> 810.5 | G33: =F33 -> 810.5 | H33: =G33 -> 810.5 | I33: =H33 -> 810.5 | J33: =I33 -> 810.5 | K33: =J33 -> 810.5 | L33: =K33 -> 810.5 | ... O33: =N33 -> 810.5
A34: Aurelio Marchini Santos - Convenio Medico | B34: =SUM(D34:O34) -> 19742.82 | D34: =(3290.47/2) -> 1645.235 | E34: =(3290.47/2) -> 1645.235 | F34: =(3290.47/2) -> 1645.235 | G34: =(3290.47/2) -> 1645.235 | H34: =(3290.47/2) -> 1645.235 | I34: =(3290.47/2) -> 1645.235 | J34: =(3290.47/2) -> 1645.235 | K34: =(3290.47/2) -> 1645.235 | L34: =(3290.47/2) -> 1645.235 | M34: =(3290.47/2)*[2]Premissas!B30+'Orçamento 2026'!L34 -> 1645.235 | N34: =M34 -> 1645.235 | O34: =N34 -> 1645.235
A35: Aurelio Marchini Santos - AASP | B35: =SUM(D35:O35) -> 1100 | E35: 100 | F35: 100 | G35: 100 | H35: 100 | I35: 100 | J35: 100 | K35: 100 | L35: 100 | M35: 100 | N35: 100 | O35: 100
A36: Bruno Micalli Pedrinelli - Distribuição Mensal Fixa | B36: =SUM(D36:O36) -> 96454.56 | D36: ='[2]Tabela 2025 2026'!Q5 -> 8037.88 | E36: =D36 -> 8037.88 | F36: =E36 -> 8037.88 | G36: =F36 -> 8037.88 | H36: =G36 -> 8037.88 | I36: =H36 -> 8037.88 | J36: =I36 -> 8037.88 | K36: =J36 -> 8037.88 | L36: =K36 -> 8037.88 | ... O36: =N36 -> 8037.88
A37: Bruno Micalli Pedrinelli - Pro Labore | B37: =SUM(D37:O37) -> 19452 | D37: ='[2]Tabela 2025 2026'!M5 -> 1621 | E37: =D37 -> 1621 | F37: =E37 -> 1621 | G37: =F37 -> 1621 | H37: =G37 -> 1621 | I37: =H37 -> 1621 | J37: =I37 -> 1621 | K37: =J37 -> 1621 | L37: =K37 -> 1621 | ... O37: =N37 -> 1621
A38: Bruno Micalli Pedrinelli - Convenio Medico | B38: =SUM(D38:O38) -> 16344.36 | D38: 1312.8 | E38: 1312.8 | F38: 1312.8 | G38: 1312.8 | H38: 1312.8 | I38: 1312.8 | J38: 1312.8 | K38: 1312.8 | L38: 1312.8 | M38: =1312.8*[2]Premissas!$B$4+'Orçamento 2026'!L38 -> 1509.72 | N38: =M38 -> 1509.72 | O38: =N38 -> 1509.72
A39: Bruno Micalli Pedrinelli - Reajuste de Distribuição Mensal Fixa | B39: =SUM(D39:O39) -> 0
A40: Elisa Hime Funari - Distribuição Mensal Fixa | B40: =SUM(D40:O40) -> 142548 | D40: ='[2]Tabela 2025 2026'!Q7 -> 11879 | E40: =D40 -> 11879 | F40: =E40 -> 11879 | G40: =F40 -> 11879 | H40: =G40 -> 11879 | I40: =H40 -> 11879 | J40: =I40 -> 11879 | K40: =J40 -> 11879 | L40: =K40 -> 11879 | ... O40: =N40 -> 11879
...

Sheet Rateio Mensal
A1: JANEIRO | E1: Orçado | H1: DESPESAS RATEADAS | K1: Rateio anual
A2: =K2 -> Custo equipe - Contencioso | B2: ='Base_Resultado Mensal_V2'!C5 -> 73576.315 | C2: =+B2/B5 -> 0.34830232 | E2: ='Areas Sintetico atualizado'!B39 -> 75454.065 | F2: =E2/$E$5 -> 0.34966985 | H2: =('Base_Resultado Mensal_V2'!C198)-'Base_Resultado Mensal_V2'!C204-'Base_Resultado Mensal_V2'!C205-'Base_Resultado Mensal_V2'!C206 -> 97103.51 | I2: =$H$2*C2 -> 33821.378 | K2: ='DRE 2026'!A6 -> Custo equipe - Contencioso | L2: ='DRE 2026'!B6 -> 901597.73 | M2: =L2/$L$5 -> 0.36967231
A3: =K3 -> Custo equipe - Econômico | B3: ='Base_Resultado Mensal_V2'!C30 -> 75653.195 | C3: =+B3/B5 -> 0.35813404 | E3: ='Areas Sintetico atualizado'!B57 -> 76879.165 | F3: =E3/$E$5 -> 0.35627406 | I3: =$H$2*C3 -> 34776.073 | K3: ='DRE 2026'!A7 -> Custo equipe - Econômico | L3: ='DRE 2026'!B7 -> 914114.75 | M3: =L3/$L$5 -> 0.37480453
A4: =K4 -> Custo equipe - Arbitragem e Compliance | B4: ='Base_Resultado Mensal_V2'!C60 -> 62013.17 | C4: =B4/$B$5 -> 0.29356364 | E4: ='Areas Sintetico atualizado'!B75 -> 63453.36 | F4: =E4/$E$5 -> 0.29405609 | I4: =$H$2*C4 -> 28506.06 | K4: ='DRE 2026'!A8 -> Custo equipe - Arbitragem e Compliance | L4: ='DRE 2026'!B8 -> 623198.16 | M4: =L4/$L$5 -> 0.25552316
A5: Total das Áreas | B5: =SUM(B2:B4) -> 211242.68 | C5: =SUM(C2:C4) -> 1 | E5: =SUM(E2:E4) -> 215786.59 | K5: =A5 -> Total das Áreas | L5: =SUM(L2:L4) -> 2438910.6 | M5: =SUM(M2:M4) -> 1
A7: FEVEREIRO | L7: 12
A8: =K2 -> Custo equipe - Contencioso | B8: ='Base_Resultado Mensal_V2'!D5 -> 76342.345 | C8: =+B8/B11 -> 0.35188306 | E8: ='DRE 2026'!D6 -> 74454.065 | F8: =E8/$E$11 -> 0.35171838 | H8: ='Base_Resultado Mensal_V2'!D207 -> 86988.31 | I8: =$H$8*C8 -> 30609.712 | L8: =L2/$L$7 -> 75133.145 | M8: =L8-B8 -> -1209.2005
A9: =K3 -> Custo equipe - Econômico | B9: ='Base_Resultado Mensal_V2'!D30 -> 78817.055 | C9: =+B9/B11 -> 0.36328968 | E9: ='DRE 2026'!D7 -> 75379.165 | F9: =E9/$E$11 -> 0.35608852 | I9: =$H$8*C9 -> 31601.955 | L9: =L3/$L$7 -> 76176.229 | M9: =L9-B9 -> -2640.8256
A10: =K4 -> Custo equipe - Arbitragem e Compliance | B10: ='Base_Resultado Mensal_V2'!D60 -> 61794.34 | C10: =B10/$B$11 -> 0.28482726 | E10: ='DRE 2026'!D8 -> 61853.36 | F10: =E10/$E$11 -> 0.2921931 | I10: =$H$8*C10 -> 24776.642 | L10: =L4/$L$7 -> 51933.18 | M10: =L10-B10 -> -9861.1599
A11: =K5 -> Total das Áreas | B11: =SUM(B8:B10) -> 216953.74 | C11: =SUM(C8:C10) -> 1 | E11: =SUM(E8:E10) -> 211686.59
A13: MARÇO
A14: =A2 -> Custo equipe - Contencioso | B14: ='Base_Resultado Mensal_V2'!E5 -> 72845.495 | C14: =+B14/B17 -> 0.36775905 | E14: ='DRE 2026'!E6 -> 74454.065 | F14: =E14/$E$17 -> 0.3740102 | H14: ='Base_Resultado Mensal_V2'!E207 -> 93764.68 | I14: =$H$14*C14 -> 34482.809
A15: =A3 -> Custo equipe - Econômico | B15: ='Base_Resultado Mensal_V2'!E30 -> 76049.975 | C15: =+B15/B17 -> 0.3839368 | E15: ='DRE 2026'!E7 -> 75379.165 | F15: =E15/$E$17 -> 0.37865732 | I15: =$H$14*C15 -> 35999.711
A16: =A4 -> Custo equipe - Arbitragem e Compliance | B16: ='Base_Resultado Mensal_V2'!E60 -> 49183.94 | C16: =B16/$B$17 -> 0.24830415 | E16: ='DRE 2026'!E8 -> 49236.38 | F16: =E16/$E$17 -> 0.24733248 | I16: =$H$14*C16 -> 23282.159
A17: =A5 -> Total das Áreas | B17: =SUM(B14:B16) -> 198079.41 | C17: =SUM(C14:C16) -> 1 | E17: =SUM(E14:E16) -> 199069.61
A19: ABRIL
A20: =A8 -> Custo equipe - Contencioso | B20: ='Base_Resultado Mensal_V2'!F5 -> 75374.055 | C20: =+B20/B23 -> 0.35965566 | E20: ='DRE 2026'!F6 -> 76054.065 | F20: =E20/$E$23 -> 0.37305249 | H20: ='Base_Resultado Mensal_V2'!F207 -> 101209.18 | I20: =$H$20*C20 -> 36400.455
A21: =A9 -> Custo equipe - Econômico | B21: ='Base_Resultado Mensal_V2'!F30 -> 79160.085 | C21: =+B21/B23 -> 0.37772112 | E21: ='DRE 2026'!F7 -> 76979.165 | F21: =E21/$E$23 -> 0.37759019 | I21: =$H$20*C21 -> 38228.845
A22: =A10 -> Custo equipe - Arbitragem e Compliance | B22: ='Base_Resultado Mensal_V2'!F60 -> 55038.69 | C22: =B22/$B$23 -> 0.26262321 | E22: ='DRE 2026'!F8 -> 50836.38 | F22: =E22/$E$23 -> 0.24935732 | I22: =$H$20*C22 -> 26579.88
A23: =A11 -> Total das Áreas | B23: =SUM(B20:B22) -> 209572.83 | C23: =SUM(C20:C22) -> 1 | E23: =SUM(E20:E22) -> 203869.61
A25: MAIO
A26: =A14 -> Custo equipe - Contencioso | B26: ='Base_Resultado Mensal_V2'!G5 -> 74141.215 | C26: =+B26/B29 -> 0.35651431 | E26: ='DRE 2026'!G6 -> 74454.065 | F26: =E26/$E$23 -> 0.36520433 | H26: ='Base_Resultado Mensal_V2'!G207 -> 99730.65 | I26: =$H$26*C26 -> 35555.404
A27: =A15 -> Custo equipe - Econômico | B27: ='Base_Resultado Mensal_V2'!G30 -> 79436.245 | C27: =+B27/B29 -> 0.38197591 | E27: ='DRE 2026'!G7 -> 75379.165 | F27: =E27/$E$23 -> 0.36974204 | I27: =$H$26*C27 -> 38094.706
A28: =A16 -> Custo equipe - Arbitragem e Compliance | B28: ='Base_Resultado Mensal_V2'!G60 -> 54383.94 | C28: =B28/$B$29 -> 0.26150978 | E28: ='DRE 2026'!G8 -> 49236.38 | F28: =E28/$E$23 -> 0.24150917 | I28: =$H$26*C28 -> 26080.54
A29: =A17 -> Total das Áreas | B29: =SUM(B26:B28) -> 207961.4 | C29: =SUM(C26:C28) -> 1 | E29: =SUM(E26:E28) -> 199069.61

Sheet Fluxo consolidado 
B1: 671666.67
B2: Janeiro | C2: Fevereiro | D2: Março | E2: Abril | F2: Maio | G2: Junho | H2: Julho | I2: Agosto | J2: Setembro | K2: Outubro | L2: Novembro | M2: Dezembro | N2: 1
A3: Contencioso | B3: Realizado | C3: Realizado | D3: Realizado | E3: Realizado | F3: Realizado | G3: Realizado | H3: Realizado | I3: Realizado | J3: Realizado | K3: Realizado | L3: Realizado | M3: Realizado | N3: TOTAL
A4: Recebimento | B4: ='Areas Sintetico atualizado'!C36 -> 38071 | C4: ='Areas Sintetico atualizado'!G36 -> 159539 | D4: ='Areas Sintetico atualizado'!K36 -> 159925 | E4: ='Areas Sintetico atualizado'!O36 -> 56461 | N4: =B4+C4+D4+E4+F4+G4+H4+I4+J4+K4+L4+M4 -> 413996 | P4: Minimo de receita
A5: Equipe | B5: ='Areas Sintetico atualizado'!C39+'Areas Sintetico atualizado'!C40 -> 73576.315 | C5: ='Areas Sintetico atualizado'!G39 -> 76342.345 | D5: ='Areas Sintetico atualizado'!K39 -> 72845.495 | E5: ='Areas Sintetico atualizado'!O39 -> 75374.055 | N5: =B5+C5+D5+E5+F5+G5+H5+I5+J5+K5+L5+M5 -> 298138.21 | P5: =(N5+N6+N7+N8)/$N$2 -> 516667.89
A6: Despesas | B6: ='Areas Sintetico atualizado'!C41+'Areas Sintetico atualizado'!C42 -> 34881.473 | C6: ='Areas Sintetico atualizado'!G41+'Areas Sintetico atualizado'!G42+'Areas Sintetico atualizado'!G40 -> 32739.031 | D6: ='Areas Sintetico atualizado'!K41+'Areas Sintetico atualizado'!K42 -> 36829.528 | E6: ='Areas Sintetico atualizado'!O40+'Areas Sintetico atualizado'!O41+'Areas Sintetico atualizado'!O42 -> 40584.373 | N6: =B6+C6+D6+E6+F6+G6+H6+I6+J6+K6+L6+M6 -> 145034.4
A7: Impostos | B7: ='Areas Sintetico atualizado'!C46 -> 5710.65 | C7: ='Areas Sintetico atualizado'!G46 -> 23930.85 | D7: ='Areas Sintetico atualizado'!K46 -> 23988.75 | E7: ='Areas Sintetico atualizado'!O46 -> 8469.15 | N7: =B7+C7+D7+E7+F7+G7+H7+I7+J7+K7+L7+M7 -> 62099.4 | P7: Margem Liq.
A8: Investimento amortizaçao | B8: ='Areas Sintetico atualizado'!C47 -> 2827.1699 | C8: ='Areas Sintetico atualizado'!G47 -> 2856.2348 | D8: ='Areas Sintetico atualizado'!K47 -> 2856.2348 | E8: ='Areas Sintetico atualizado'!O47 -> 2856.2348 | N8: =B8+C8+D8+E8+F8+G8+H8+I8+J8+K8+L8+M8 -> 11395.874
A9: Margem liquida | B9: =B4-B5-B6-B7-B8 -> -78924.607 | C9: =C4-C5-C6-C7-C8 -> 23670.54 | D9: =D4-D5-D6-D7-D8 -> 23404.993 | E9: =E4-E5-E6-E7-E8 -> -70822.813 | F9: =F4-F5-F6-F7-F8 -> 0 | G9: =G4-G5-G6-G7-G8 -> 0 | H9: =H4-H5-H6-H7-H8 -> 0 | I9: =I4-I5-I6-I7-I8 -> 0 | ... N9: =N4-N5-N6-N7-N8 -> -102671.89 | P9: =N9/N4 -> -0.24800213
B11: Janeiro | C11: Fevereiro | D11: Março | E11: Abril | F11: Maio | G11: Junho | H11: Julho | I11: Agosto | J11: Setembro | K11: =K2 -> Outubro | L11: =L2 -> Novembro | M11: =M2 -> Dezembro
A12: Economico | B12: Realizado | C12: Realizado | D12: Realizado | E12: Realizado | F12: Realizado | G12: Realizado | H12: Realizado | I12: Realizado | J12: Realizado | K12: Realizado | L12: Realizado | M12: Realizado | N12: TOTAL
A13: Recebimento | B13: ='Areas Sintetico atualizado'!C54 -> 61844 | C13: ='Areas Sintetico atualizado'!G54 -> 119667 | D13: ='Areas Sintetico atualizado'!K54 -> 343893 | E13: ='Areas Sintetico atualizado'!O54 -> 159921 | N13: =B13+C13+D13+E13+F13+G13+H13+I13+J13+K13+L13+M13 -> 685325 | P13: Minimo de receita
A14: Equipe | B14: ='Areas Sintetico atualizado'!C57 -> 75653.195 | C14: ='Areas Sintetico atualizado'!G57 -> 78817.055 | D14: ='Areas Sintetico atualizado'!K57 -> 76049.975 | E14: ='Areas Sintetico atualizado'!O57 -> 79160.085 | N14: =B14+C14+D14+E14+F14+G14+H14+I14+J14+K14+L14+M14 -> 309680.31 | P14: =(N14+N15+N16+N17)/$N$2 -> 575765.6
A15: Despesas | B15: ='Areas Sintetico atualizado'!C59+'Areas Sintetico atualizado'!C60 -> 36647.878 | C15: ='Areas Sintetico atualizado'!G58+'Areas Sintetico atualizado'!G59+'Areas Sintetico atualizado'!G60 -> 36398.024 | D15: ='Areas Sintetico atualizado'!K59+'Areas Sintetico atualizado'!K60 -> 38129.03 | E15: ='Areas Sintetico atualizado'!O58+'Areas Sintetico atualizado'!O59+'Areas Sintetico atualizado'!O60 -> 40358.164 | N15: =B15+C15+D15+E15+F15+G15+H15+I15+J15+K15+L15+M15 -> 151533.09
A16: Impostos | B16: ='Areas Sintetico atualizado'!C64 -> 9276.6 | C16: ='Areas Sintetico atualizado'!G64 -> 17950.05 | D16: ='Areas Sintetico atualizado'!K64 -> 51583.95 | E16: ='Areas Sintetico atualizado'!O64 -> 23988.15 | N16: =B16+C16+D16+E16+F16+G16+H16+I16+J16+K16+L16+M16 -> 102798.75 | P16: Margem Liq.
A17: Investimento amortizaçao | B17: ='Areas Sintetico atualizado'!C65 -> 2906.974 | C17: ='Areas Sintetico atualizado'!G65 -> 2948.8223 | D17: ='Areas Sintetico atualizado'!K65 -> 2948.8223 | E17: ='Areas Sintetico atualizado'!O65 -> 2948.8223 | N17: =B17+C17+D17+E17+F17+G17+H17+I17+J17+K17+L17+M17 -> 11753.441
A18: Margem liquida | B18: =B13-B14-B15-B16-B17 -> -62640.647 | C18: =C13-C14-C15-C16-C17 -> -16446.951 | D18: =D13-D14-D15-D16-D17 -> 175181.22 | E18: =E13-E14-E15-E16-E17 -> 13465.779 | F18: =F13-F14-F15-F16-F17 -> 0 | G18: =G13-G14-G15-G16-G17 -> 0 | H18: =H13-H14-H15-H16-H17 -> 0 | I18: =I13-I14-I15-I16-I17 -> 0 | ... N18: =N13-N14-N15-N16-N17 -> 109559.4 | P18: =N18/N13 -> 0.15986489
B20: Janeiro | C20: Fevereiro | D20: Março | E20: Abril | F20: Maio | G20: Junho | H20: Julho | I20: Agosto | J20: Setembro | K20: =K2 -> Outubro | L20: =L2 -> Novembro | M20: =M2 -> Dezembro
A21: Arbitragem | B21: Realizado | C21: Realizado | D21: Realizado | E21: Realizado | F21: Realizado | G21: Realizado | H21: Realizado | I21: Realizado | J21: Realizado | K21: Realizado | L21: Realizado | M21: Realizado | N21: TOTAL
A22: Recebimento | B22: ='Areas Sintetico atualizado'!C72 -> 133169 | C22: ='Areas Sintetico atualizado'!G72 -> 62506 | D22: ='Areas Sintetico atualizado'!K72 -> 113444 | E22: ='Areas Sintetico atualizado'!O72 -> 3476 | N22: =B22+C22+D22+E22+F22+G22+H22+I22+J22+K22+L22+M22 -> 312595 | P22: Minimo de receita
A23: Equipe | B23: ='Areas Sintetico atualizado'!C75 -> 62013.17 | C23: ='Areas Sintetico atualizado'!G75 -> 61794.34 | D23: ='Areas Sintetico atualizado'!K75 -> 49183.94 | E23: ='Areas Sintetico atualizado'!O75 -> 55038.69 | N23: =B23+C23+D23+E23+F23+G23+H23+I23+J23+K23+L23+M23 -> 228030.14 | P23: =(N23+N24+N25+N26)/$N$2 -> 396524.39
A24: Despesas | B24: ='Areas Sintetico atualizado'!C77+'Areas Sintetico atualizado'!C78 -> 28652.06 | C24: ='Areas Sintetico atualizado'!G76+'Areas Sintetico atualizado'!G77+'Areas Sintetico atualizado'!G78 -> 27410.336 | D24: ='Areas Sintetico atualizado'!K77+'Areas Sintetico atualizado'!K78 -> 27010.343 | E24: ='Areas Sintetico atualizado'!O76+'Areas Sintetico atualizado'!O77+'Areas Sintetico atualizado'!O78 -> 29213.573 | N24: =B24+C24+D24+E24+F24+G24+H24+I24+J24+K24+L24+M24 -> 112286.31
A25: Impostos | B25: ='Areas Sintetico atualizado'!C82 -> 19975.35 | C25: ='Areas Sintetico atualizado'!G82 -> 9375.9 | D25: ='Areas Sintetico atualizado'!K82 -> 17016.6 | E25: ='Areas Sintetico atualizado'!O82 -> 521.4 | N25: =B25+C25+D25+E25+F25+G25+H25+I25+J25+K25+L25+M25 -> 46889.25 | P25: Margem Liq.
A26: Investimento amortizaçao | B26: ='Areas Sintetico atualizado'!C83 -> 2382.8561 | C26: ='Areas Sintetico atualizado'!G83 -> 2311.9429 | D26: ='Areas Sintetico atualizado'!K83 -> 2311.9429 | E26: ='Areas Sintetico atualizado'!O83 -> 2311.9429 | N26: =B26+C26+D26+E26+F26+G26+H26+I26+J26+K26+L26+M26 -> 9318.6847
A27: Margem liquida | B27: =B22-B23-B24-B25-B26 -> 20145.564 | C27: =C22-C23-C24-C25-C26 -> -38386.518 | D27: =D22-D23-D24-D25-D26 -> 17921.174 | E27: =E22-E23-E24-E25-E26 -> -83609.606 | F27: =F22-F23-F24-F25-F26 -> 0 | G27: =G22-G23-G24-G25-G26 -> 0 | H27: =H22-H23-H24-H25-H26 -> 0 | I27: =I22-I23-I24-I25-I26 -> 0 | ... N27: =N22-N23-N24-N25-N26 -> -83929.386 | P27: =N27/N22 -> -0.26849241
B30: =B4+B13+B22 -> 233084 | C30: =C4+C13+C22 -> 341712 | D30: =D4+D13+D22 -> 617262 | E30: =E4+E13+E22 -> 219858 | F30: =F4+F13+F22 -> 0 | G30: =G4+G13+G22 -> 0 | H30: =H4+H13+H22 -> 0 | I30: =I4+I13+I22 -> 0 | ... M30: =M4+M13+M22 -> 0 | N30: =B30+C30+D30+E30+F30+G30+H30+I30+J30+K30+L30+M30 -> 1411916
N31: =N5+N14+N23 -> 835848.66

Sheet Base_Resultado Mensal_V2
A2: Resultado Financeiro 2026 | B2: ANUAL | C2: Janeiro | D2: Fevereiro | E2: Março | F2: Abril | G2: Maio | H2: Junho | I2: Julho | J2: Agosto | K2: Setembro | L2: Outubro | M2: Novembro | N2: Dezembro
A3: Movimentação de Entradas | C3: =SUM(C4:C4) -> 279821.07 | D3: =SUM(D4:D4) -> 319233.58 | E3: =SUM(E4:E4) -> 612501.76 | F3: =SUM(F4:F4) -> 238327.46 | G3: =SUM(G4:G4) -> 415928 | H3: =SUM(H4:H4) -> 0 | I3: =SUM(I4:I4) -> 0 | J3: =SUM(J4:J4) -> 0 | ... N3: =SUM(N4:N4) -> 0
A4: Receita de honorários | B4: =SUM(C4:N4) -> 1865811.9 | C4: 279821.07 | D4: 319233.58 | E4: 612501.76 | F4: 238327.46 | G4: 415928 | O4: =C4+D4+E4+F4+G4+H4+I4+J4+K4+L4+M4+N4 -> 1865811.9
A5: Custo equipe - Contencioso | B5: =SUM(C5:N5) -> 372279.42 | C5: =SUM(C6:C27) -> 73576.315 | D5: =SUM(D6:D27) -> 76342.345 | E5: =SUM(E6:E27) -> 72845.495 | F5: =SUM(F6:F27) -> 75374.055 | G5: =SUM(G6:G27) -> 74141.215 | H5: =SUM(H6:H27) -> 0 | I5: =SUM(I6:I27) -> 0 | J5: =SUM(J6:J27) -> 0 | ... N5: =SUM(N6:N27) -> 0 | O5: =C5+D5+E5+F5+G5+H5+I5+J5+K5+L5+M5+N5 -> 372279.42
A6: Aurelio Marchini Santos - Convenio Medico | B6: =SUM(C6:N6) -> 8752.795 | C6: =3182.83/2 -> 1591.415 | D6: =3182.83/2 -> 1591.415 | E6: =3182.83/2 -> 1591.415 | F6: =3182.83/2 -> 1591.415 | G6: =4774.27/2 -> 2387.135 | O6: =C6+D6+E6+F6+G6+H6+I6+J6+K6+L6+M6+N6 -> 8752.795
A7: Aurelio Marchini Santos - Distribuição Mensal Fixa | B7: =SUM(C7:N7) -> 58447.5 | C7: =12500-C8 -> 11689.5 | D7: =12500-D8 -> 11689.5 | E7: =12500-E8 -> 11689.5 | F7: =12500-F8 -> 11689.5 | G7: =12500-G8 -> 11689.5 | O7: =C7+D7+E7+F7+G7+H7+I7+J7+K7+L7+M7+N7 -> 58447.5
A8: Aurelio Marchini Santos- Pro labore | B8: =SUM(C8:N8) -> 4052.5 | C8: 810.5 | D8: 810.5 | E8: =1621/2 -> 810.5 | F8: =1621/2 -> 810.5 | G8: =1621/2 -> 810.5 | O8: =C8+D8+E8+F8+G8+H8+I8+J8+K8+L8+M8+N8 -> 4052.5
A9: Aurelio Marchini Santos- AASP | B9: =SUM(C9:N9) -> 54.35 | D9: =108.7/2 -> 54.35
A10: Beatriz Baes Xavier - Convenio Medico | B10: =SUM(C10:N10) -> 6347.3 | C10: 1269.46 | D10: 1269.46 | E10: 1269.46 | F10: 1269.46 | G10: 1269.46 | O10: =C10+D10+E10+F10+G10+H10+I10+J10+K10+L10+M10+N10 -> 6347.3
A11: Beatriz Baes Xavier - Despesas Extras - Cartao Predio | B11: =SUM(C11:N11) -> 0 | O11: =C11+D11+E11+F11+G11+H11+I11+J11+K11+L11+M11+N11 -> 0
A12: Beatriz Baes Xavier - Distribuição Mensal Fixa | B12: =SUM(C12:N12) -> 38168.6 | C12: =8640-C13 -> 7019 | D12: =9158.4-D13 -> 7537.4 | E12: =9158.4-E13 -> 7537.4 | F12: =9158.4-F13+500 -> 8037.4 | G12: =9158.4-G13+500 -> 8037.4 | O12: =C12+D12+E12+F12+G12+H12+I12+J12+K12+L12+M12+N12 -> 38168.6
A13: Beatriz Baes Xavier - Pro Labore | B13: =SUM(C13:N13) -> 8105 | C13: 1621 | D13: 1621 | E13: 1621 | F13: 1621 | G13: 1621 | O13: =C13+D13+E13+F13+G13+H13+I13+J13+K13+L13+M13+N13 -> 8105
A14: Beatriz Baes Xavier - Reajuste de Distribuição Mensal Fixa | B14: =SUM(C14:N14) -> 518.4 | D14: 518.4 | O14: =C14+D14+E14+F14+G14+H14+I14+J14+K14+L14+M14+N14 -> 518.4
A15: Daniel Costa Caselta - Convenio Medico | B15: =SUM(C15:N15) -> 8680.7 | C15: 1736.14 | D15: 1736.14 | E15: 1736.14 | F15: 1736.14 | G15: 1736.14 | O15: =C15+D15+E15+F15+G15+H15+I15+J15+K15+L15+M15+N15 -> 8680.7
A16: Daniel Costa Caselta - Distribuição Mensal Fixa | B16: =SUM(C16:N16) -> 116895 | C16: =25000-C17 -> 23379 | D16: =25000-D17 -> 23379 | E16: =25000-E17 -> 23379 | F16: =25000-F17 -> 23379 | G16: =25000-G17 -> 23379 | O16: =C16+D16+E16+F16+G16+H16+I16+J16+K16+L16+M16+N16 -> 116895
A17: Daniel Costa Caselta - Pro labore | B17: =SUM(C17:N17) -> 8105 | C17: 1621 | D17: 1621 | E17: 1621 | F17: 1621 | G17: 1621 | O17: =C17+D17+E17+F17+G17+H17+I17+J17+K17+L17+M17+N17 -> 8105
A18: Daniel Costa Caselta - AASP | B18: =SUM(C18:N18) -> 206.4 | C18: 97.7 | D18: 108.7 | O18: =C18+D18+E18+F18+G18+H18+I18+J18+K18+L18+M18+N18 -> 206.4
A19: Isabel de Almeida Rego Campinho - Convenio Medico | B19: =SUM(C19:N19) -> 7820.4 | C19: 1564.08 | D19: 1564.08 | E19: 1564.08 | F19: 1564.08 | G19: 1564.08 | O19: =C19+D19+E19+F19+G19+H19+I19+J19+K19+L19+M19+N19 -> 7820.4
A20: Isabel de Almeida Rego Campinho - Distribuição Mensal Fixa | B20: =SUM(C20:N20) -> 76459 | C20: =15660-C21 -> 14039 | D20: =17226-D21 -> 15605 | E20: =17226-E21 -> 15605 | F20: =17226-F21 -> 15605 | G20: =17226-G21 -> 15605 | O20: =C20+D20+E20+F20+G20+H20+I20+J20+K20+L20+M20+N20 -> 76459
A21: Isabel de Almeida Rego Campinho - Pro Labore | B21: =SUM(C21:N21) -> 8105 | C21: 1621 | D21: 1621 | E21: 1621 | F21: 1621 | G21: 1621 | O21: =C21+D21+E21+F21+G21+H21+I21+J21+K21+L21+M21+N21 -> 8105
A22: Isabel de Almeida Rego Campinho - Reajuste de Distribuição Mensal Fixa | B22: =SUM(C22:N22) -> 1566 | D22: 1566 | O22: =C22+D22+E22+F22+G22+H22+I22+J22+K22+L22+M22+N22 -> 1566
A23: João Victor Santos de Oliveira - Bolsa auxilio / IR Estagiários | B23: =SUM(C23:N23) -> 14000 | C23: 2800 | D23: 2800 | E23: 2800 | F23: 2800 | G23: 2800 | O23: =C23+D23+E23+F23+G23+H23+I23+J23+K23+L23+M23+N23 -> 14000
A24: João Victor Santos de Oliveira - Seguro de Vida | B24: =SUM(C24:N24) -> 0 | O24: =C24+D24+E24+F24+G24+H24+I24+J24+K24+L24+M24+N24 -> 0
A25: ISS Trimestral | B25: =SUM(C25:N25) -> 3748.28 | C25: =382.16*4+191.08 -> 1719.72 | F25: =507.14*4 -> 2028.56 | O25: =C25+D25+E25+F25+G25+H25+I25+J25+K25+L25+M25+N25 -> 3748.28
A26: Vale Refeição | B26: =SUM(C26:N26) -> 1844 | C26: 829.8 | D26: 1014.2 | O26: =C26+D26+E26+F26+G26+H26+I26+J26+K26+L26+M26+N26 -> 1844
A27: Vale Transporte | B27: =SUM(C27:N27) -> 403.2 | C27: 168 | D27: 235.2 | O27: =C27+D27+E27+F27+G27+H27+I27+J27+K27+L27+M27+N27 -> 403.2
A28: Participação/Comissão - Contencioso | B28: =SUM(C28:N28) -> 0 | O28: =C28+D28+E28+F28+G28+H28+I28+J28+K28+L28+M28+N28 -> 0
A29: Repasse - Contencioso | B29: =SUM(C29:N29) -> 0 | O29: =C29+D29+E29+F29+G29+H29+I29+J29+K29+L29+M29+N29 -> 0
A30: Custo equipe - Econômico | B30: =SUM(B31:B57) -> 389116.56 | C30: =SUM(C31:C57) -> 75653.195 | D30: =SUM(D31:D57) -> 78817.055 | E30: =SUM(E31:E57) -> 76049.975 | F30: =SUM(F31:F57) -> 79160.085 | G30: =SUM(G31:G57) -> 79436.245 | H30: =SUM(H31:H57) -> 0 | I30: =SUM(I31:I57) -> 0 | ... N30: =SUM(N31:N57) -> 0 | O30: =C30+D30+E30+F30+G30+H30+I30+J30+K30+L30+M30+N30 -> 389116.55
A31: Andrielly da Silva Gonsalves - Convenio Medico | B31: =SUM(C31:N31) -> 5642.76 | C31: 1269.46 | D31: 564.92 | E31: 1269.46 | F31: 1269.46 | G31: 1269.46 | O31: =C31+D31+E31+F31+G31+H31+I31+J31+K31+L31+M31+N31 -> 5642.76
A32: Andrielly da Silva Gonsalves - Distribuição Mensal Fixa | B32: =SUM(C32:N32) -> 18457 | C32: =5200-C33 -> 3579 | D32: =5720-D33 -> 4099 | E32: =6220-E33-1509 -> 3090 | F32: =6220-F33-1509 -> 3090 | G32: =6220-G33 -> 4599 | O32: =C32+D32+E32+F32+G32+H32+I32+J32+K32+L32+M32+N32 -> 18457
A33: Andrielly da Silva Gonsalves - Pro Labore | B33: =SUM(C33:N33) -> 8105 | C33: 1621 | D33: 1621 | E33: 1621 | F33: 1621 | G33: 1621 | O33: =C33+D33+E33+F33+G33+H33+I33+J33+K33+L33+M33+N33 -> 8105
A34: Andrielly da Silva Gonsalves - Subsidio de Pós | B34: =SUM(C34:N34) -> 3018 | D34: =1509+1509 -> 3018 | O34: =C34+D34+E34+F34+G34+H34+I34+J34+K34+L34+M34+N34 -> 3018
A35: Andrielly da Silva Gonsalves - Reajuste de Distribuição Mensal Fixa | B35: =SUM(C35:N35) -> 520 | D35: 520 | O35: =C35+D35+E35+F35+G35+H35+I35+J35+K35+L35+M35+N35 -> 520
A36: Aurelio Marchini Santos - AASP | B36: =SUM(C36:N36) -> 152.05 | C36: 97.7 | D36: =108.7/2 -> 54.35 | O36: =C36+D36+E36+F36+G36+H36+I36+J36+K36+L36+M36+N36 -> 152.05
A37: Aurelio Marchini Santos - Convenio Medico | B37: =SUM(C37:N37) -> 8752.795 | C37: =3182.83/2 -> 1591.415 | D37: =3182.83/2 -> 1591.415 | E37: =3182.83/2 -> 1591.415 | F37: =3182.83/2 -> 1591.415 | G37: =4774.27/2 -> 2387.135 | O37: =C37+D37+E37+F37+G37+H37+I37+J37+K37+L37+M37+N37 -> 8752.795
A38: Aurelio Marchini Santos - Distribuição Mensal Fixa | B38: =SUM(C38:N38) -> 58447.5 | C38: =12500-C39 -> 11689.5 | D38: =12500-D39 -> 11689.5 | E38: =12500-E39 -> 11689.5 | F38: =12500-F39 -> 11689.5 | G38: =12500-G39 -> 11689.5 | O38: =C38+D38+E38+F38+G38+H38+I38+J38+K38+L38+M38+N38 -> 58447.5
A39: Aurelio Marchini Santos- Pro labore | B39: =SUM(C39:N39) -> 4052.5 | C39: 810.5 | D39: 810.5 | E39: =1621/2 -> 810.5 | F39: =1621/2 -> 810.5 | G39: =1621/2 -> 810.5 | O39: =C39+D39+E39+F39+G39+H39+I39+J39+K39+L39+M39+N39 -> 4052.5
A40: Bruno Micalli Pedrinelli - Convenio Medico | B40: =SUM(C40:N40) -> 5642.76 | C40: 1269.46 | D40: 564.92 | E40: 1269.46 | F40: 1269.46 | G40: 1269.46 | O40: =C40+D40+E40+F40+G40+H40+I40+J40+K40+L40+M40+N40 -> 5642.76
A41: Bruno Micalli Pedrinelli - Distribuição Mensal Fixa | B41: =SUM(C41:N41) -> 43177.88 | C41: =8624-C42 -> 7003 | D41: =9658.88-D42 -> 8037.88 | E41: =11000-E42 -> 9379 | F41: =11000-F42 -> 9379 | G41: =11000-G42 -> 9379 | O41: =C41+D41+E41+F41+G41+H41+I41+J41+K41+L41+M41+N41 -> 43177.88
...

Sheet Areas Sintetico atualizado
A1: DRE 2026 | B1: Janeiro | F1: Fevereiro | J1: Março | N1: Abril | R1: Maio | AA1: 7 | AC1: CHECK
A2: Resultado Institucional | B2: Orçado | C2: Realizado | D2: Variação Mensal | E2: Desvio% | F2: Orçado | G2: Realizado | H2: Variação Mensal | I2: Desvio% | J2: Orçado | K2: Realizado | L2: Variação Mensal | M2: Desvio% | N2: Orçado | O2: Realizado | P2: Variação Mensal | Q2: Desvio% | R2: Orçado | S2: Realizado | T2: Variação Mensal | U2: Desvio% | V2: Orçado YTG | W2: Orçado YTD | X2: Realizado | Y2: Variação | Z2: Variação Mensal | AA2: YTG
A3: Faturamento | B3: ='DRE 2026'!C3 -> 671666.67 | C3: 444545.69 | D3: =+C3-B3 -> -227120.98 | E3: =C3/B3 -> 0.66185462 | F3: ='DRE 2026'!D3 -> 671666.67 | G3: 534752.84 | H3: =+G3-F3 -> -136913.83 | I3: =G3/F3 -> 0.79615807 | J3: ='DRE 2026'!H3 -> 671666.67 | K3: 391005.89 | L3: =+K3-J3 -> -280660.78 | M3: =K3/J3 -> 0.58214276 | N3: ='DRE 2026'!F3 -> 671666.67 | O3: 282214.17 | P3: =+O3-N3 -> -389452.5 | Q3: =O3/N3 -> 0.42016998 | R3: ='DRE 2026'!J3 -> 671666.67 | S3: 719988.05 | T3: =+S3-R3 -> 48321.38 | U3: =S3/R3 -> 1.0719425 | V3: ='DRE 2026'!B3 -> 8060000 | W3: ='DRE 2026'!C3+'DRE 2026'!D3+'DRE 2026'!E3+'DRE 2026'!F3+'DRE 2026'!G3 -> 3358333.4 | X3: =C3+G3+K3+O3+S3 -> 2372506.6 | Y3: =X3-W3 -> -985826.71 | Z3: =X3/W3 -> 0.70645359 | AA3: =V3-X3 -> 5687493.4 | AC3: =C3+G3+K3+O3+S3 -> 2372506.6 | AD3: =X3-AC3 -> 0
A4: Receita | C4: ='Base_Resultado Mensal_V2'!C4 -> 279821.07 | G4: ='Base_Resultado Mensal_V2'!D4 -> 319233.58 | H4: =+G4-F3 -> -352433.09 | K4: ='Base_Resultado Mensal_V2'!E4 -> 612501.76 | L4: =+K4-J3 -> -59164.91 | O4: 238327.46 | P4: =+O4-N3 -> -433339.21 | S4: ='Base_Resultado Mensal_V2'!G4 -> 415928 | T4: =+S4-R3 -> -255738.67 | W4: ='DRE 2026'!C3+'DRE 2026'!D3+'DRE 2026'!E3+'DRE 2026'!F3 -> 2686666.7 | X4: ='Base_Resultado Mensal_V2'!B4 -> 1865811.9 | Y4: =X4-W3 -> -1492521.5 | Z4: =X4/W4 -> 0.69447092 | AC4: =C4+G4+K4+O4+S4 -> 1865811.9 | AD4: =X4-AC4 -> 0
A5: Despesas | B5: Orçado | C5: Realizado | D5: Variação Mensal | E5: Variação Mensal | F5: Orçado | G5: Realizado | H5: Variação Mensal | I5: Variação Mensal | J5: Orçado | K5: Realizado | L5: Variação Mensal | M5: Variação Mensal | N5: Orçado | O5: Realizado | P5: Variação Mensal | Q5: Variação Mensal | R5: Orçado | S5: Realizado | T5: Variação Mensal | U5: Variação Mensal | Z5: Variação Mensal
A6: Custos Diretos | B6: =SUM(B7:B11) -> 215786.59 | C6: =SUM(C7:C12) -> 211242.68 | D6: =+B6-C6 -> 4543.91 | F6: =SUM(F7:F11) -> 211686.59 | G6: =SUM(G7:G12) -> 218453.74 | H6: =+F6-G6 -> -6767.15 | J6: =SUM(J7:J11) -> 199069.61 | K6: =SUM(K7:K12) -> 198079.41 | L6: =+J6-K6 -> 990.2 | N6: =SUM(N7:N11) -> 203869.61 | O6: =SUM(O7:O12) -> 209572.83 | P6: =+N6-O6 -> -5703.22 | R6: =SUM(R7:R11) -> 199069.61 | S6: =SUM(S7:S12) -> 210089.46 | T6: =+R6-S6 -> -11019.85 | V6: =SUM(V7:V11) -> 2438910.6 | W6: =SUM(W7:W11) -> 1029482 | X6: =X7+X8+X9+X10+X11+X12 -> 1047438.1 | Y6: =W6-X6 -> -17956.11 | Z6: =X6/W6 -> 1.0174419 | AA6: =V6-X6 -> 1391472.5 | AC6: =C6+G6+K6+O6+S6 -> 1047438.1 | AD6: =X6-AC6 -> 0
A7: =+'Base_Resultado Mensal_V2'!A5 -> Custo equipe - Contencioso | B7: ='DRE 2026'!C6 -> 75454.065 | C7: ='Base_Resultado Mensal_V2'!C5 -> 73576.315 | D7: =+B7-C7 -> 1877.75 | E7: =C7/B7 -> 0.975114 | F7: ='DRE 2026'!D6 -> 74454.065 | G7: ='Base_Resultado Mensal_V2'!D5 -> 76342.345 | H7: =+F7-G7 -> -1888.28 | I7: =G7/F7 -> 1.0253617 | J7: ='DRE 2026'!H6 -> 74454.065 | K7: ='Base_Resultado Mensal_V2'!E5 -> 72845.495 | L7: =+J7-K7 -> 1608.57 | M7: =K7/J7 -> 0.97839514 | N7: ='DRE 2026'!F6 -> 76054.065 | O7: ='Base_Resultado Mensal_V2'!F5 -> 75374.055 | P7: =+N7-O7 -> 680.01 | Q7: =O7/N7 -> 0.99105886 | R7: ='DRE 2026'!J6 -> 74454.065 | S7: ='Base_Resultado Mensal_V2'!G5 -> 74141.215 | T7: =+R7-S7 -> 312.85 | U7: =S7/R7 -> 0.99579808 | V7: ='DRE 2026'!B6 -> 901597.73 | W7: ='DRE 2026'!C6+'DRE 2026'!D6+'DRE 2026'!E6+'DRE 2026'!F6+'DRE 2026'!G6 -> 374870.33 | X7: ='Base_Resultado Mensal_V2'!B5 -> 372279.42 | Y7: =W7-X7 -> 2590.9 | Z7: =X7/W7 -> 0.99308854 | AA7: =V7-X7 -> 529318.31 | AC7: =C7+G7+K7+O7+S7 -> 372279.42 | AD7: =X7-AC7 -> 0
A8: ='Base_Resultado Mensal_V2'!A28 -> Participação/Comissão - Contencioso | C8: ='Base_Resultado Mensal_V2'!C28+'Base_Resultado Mensal_V2'!C29 -> 0 | G8: ='Base_Resultado Mensal_V2'!D28+'Base_Resultado Mensal_V2'!D29 -> 0 | K8: ='Base_Resultado Mensal_V2'!E28+'Base_Resultado Mensal_V2'!E29 -> 0 | O8: ='Base_Resultado Mensal_V2'!F28+'Base_Resultado Mensal_V2'!F29 -> 0 | S8: ='Base_Resultado Mensal_V2'!G28 -> 0 | X8: ='Base_Resultado Mensal_V2'!B28+'Base_Resultado Mensal_V2'!B29 -> 0 | Y8: =W8-X8 -> 0 | AC8: =C8+G8+K8+O8+S8 -> 0 | AD8: =X8-AC8 -> 0
A9: =+'Base_Resultado Mensal_V2'!A30 -> Custo equipe - Econômico | B9: ='DRE 2026'!C7 -> 76879.165 | C9: ='Base_Resultado Mensal_V2'!C30 -> 75653.195 | D9: =+B9-C9 -> 1225.97 | E9: =C9/B9 -> 0.98405329 | F9: ='DRE 2026'!D7 -> 75379.165 | G9: ='Base_Resultado Mensal_V2'!D30 -> 78817.055 | H9: =+F9-G9 -> -3437.89 | I9: =G9/F9 -> 1.045608 | J9: ='DRE 2026'!H7 -> 75379.165 | K9: ='Base_Resultado Mensal_V2'!E30 -> 76049.975 | L9: =+J9-K9 -> -670.81 | M9: =K9/J9 -> 1.0088991 | N9: ='DRE 2026'!F7 -> 76979.165 | O9: ='Base_Resultado Mensal_V2'!F30 -> 79160.085 | P9: =+N9-O9 -> -2180.92 | Q9: =O9/N9 -> 1.0283313 | R9: ='DRE 2026'!J7 -> 75379.165 | S9: ='Base_Resultado Mensal_V2'!G30 -> 79436.245 | T9: =+R9-S9 -> -4057.08 | U9: =S9/R9 -> 1.0538223 | V9: ='DRE 2026'!B7 -> 914114.75 | W9: ='DRE 2026'!C7+'DRE 2026'!D7+'DRE 2026'!E7+'DRE 2026'!F7+'DRE 2026'!G7 -> 379995.83 | X9: ='Base_Resultado Mensal_V2'!B30 -> 389116.56 | Y9: =W9-X9 -> -9120.73 | Z9: =X9/W9 -> 1.0240022 | AA9: =V9-X9 -> 524998.2 | AC9: =C9+G9+K9+O9+S9 -> 389116.55 | AD9: =X9-AC9 -> 0
A10: ='Base_Resultado Mensal_V2'!A58 -> Participação/comissão - Economico | C10: ='Base_Resultado Mensal_V2'!C28+'Base_Resultado Mensal_V2'!C29 -> 0 | G10: ='Base_Resultado Mensal_V2'!D58+'Base_Resultado Mensal_V2'!D59 -> 1500 | K10: ='Base_Resultado Mensal_V2'!E58+'Base_Resultado Mensal_V2'!E59 -> 0 | O10: ='Base_Resultado Mensal_V2'!F58+'Base_Resultado Mensal_V2'!F59 -> 0 | S10: ='Base_Resultado Mensal_V2'!G58 -> 2128.06 | X10: ='Base_Resultado Mensal_V2'!B58+'Base_Resultado Mensal_V2'!B59 -> 3628.06 | Y10: =W10-X10 -> -3628.06 | AC10: =C10+G10+K10+O10+S10 -> 3628.06 | AD10: =X10-AC10 -> 0
A11: =+'Base_Resultado Mensal_V2'!A60 -> Custo equipe - Arbitragem e Compliance | B11: ='DRE 2026'!C8 -> 63453.36 | C11: ='Base_Resultado Mensal_V2'!C60 -> 62013.17 | D11: =+B11-C11 -> 1440.19 | E11: =C11/B11 -> 0.97730317 | F11: ='DRE 2026'!D8 -> 61853.36 | G11: ='Base_Resultado Mensal_V2'!D60 -> 61794.34 | H11: =+F11-G11 -> 59.02 | I11: =G11/F11 -> 0.99904581 | J11: ='DRE 2026'!H8 -> 49236.38 | K11: ='Base_Resultado Mensal_V2'!E60 -> 49183.94 | L11: =+J11-K11 -> 52.44 | M11: =K11/J11 -> 0.99893493 | N11: ='DRE 2026'!F8 -> 50836.38 | O11: ='Base_Resultado Mensal_V2'!F60 -> 55038.69 | P11: =+N11-O11 -> -4202.31 | Q11: =O11/N11 -> 1.0826634 | R11: ='DRE 2026'!J8 -> 49236.38 | S11: ='Base_Resultado Mensal_V2'!G60 -> 54383.94 | T11: =+R11-S11 -> -5147.56 | U11: =S11/R11 -> 1.1045479 | V11: ='DRE 2026'!B8 -> 623198.16 | W11: ='DRE 2026'!C8+'DRE 2026'!D8+'DRE 2026'!E8+'DRE 2026'!F8+'DRE 2026'!G8 -> 274615.86 | X11: ='Base_Resultado Mensal_V2'!B60 -> 282414.08 | Y11: =W11-X11 -> -7798.22 | Z11: =X11/W11 -> 1.0283968 | AA11: =V11-X11 -> 340784.08 | AC11: =C11+G11+K11+O11+S11 -> 282414.08 | AD11: =X11-AC11 -> 0
A12: ='Base_Resultado Mensal_V2'!A80 -> Participação/comissão - Arbitragem | C12: ='Base_Resultado Mensal_V2'!C80+'Base_Resultado Mensal_V2'!C81 -> 0 | G12: ='Base_Resultado Mensal_V2'!D80+'Base_Resultado Mensal_V2'!D81 -> 0 | K12: ='Base_Resultado Mensal_V2'!E80+'Base_Resultado Mensal_V2'!E81 -> 0 | O12: ='Base_Resultado Mensal_V2'!F80+'Base_Resultado Mensal_V2'!F81 -> 0 | S12: ='Base_Resultado Mensal_V2'!G80 -> 0 | X12: ='Base_Resultado Mensal_V2'!B80+'Base_Resultado Mensal_V2'!B81 -> 0 | Y12: =W12-X12 -> 0
A13: Despesas Indiretas | B13: =SUM(B14:B24) -> 102906.66 | C13: =SUM(C14:C24) -> 100181.41 | D13: =(B13-C13) -> 2725.2533 | F13: =SUM(F14:F24) -> 112483.91 | G13: =SUM(G14:G24) -> 95047.39 | H13: =(F13-G13) -> 17436.52 | J13: =SUM(J14:J24) -> 129851.12 | K13: =SUM(K14:K24) -> 101968.9 | L13: =(J13-K13) -> 27882.215 | N13: =SUM(N14:N24) -> 124351.12 | O13: =SUM(O14:O24) -> 110156.11 | P13: =(N13-O13) -> 14195.005 | R13: =SUM(R14:R24) -> 103162.07 | S13: =SUM(S14:S24) -> 105511.43 | T13: =(R13-S13) -> -2349.3645 | V13: =SUM(V14:V24) -> 1386633.4 | W13: =SUM(W14:W24) -> 572754.87 | X13: =SUM(X14:X24) -> 512865.24 | Y13: =W13-X13 -> 59889.63 | Z13: =X13/W13 -> 0.89543584 | AA13: =V13-X13 -> 873768.15 | AC13: =C13+G13+K13+O13+S13 -> 512865.24 | AD13: =X13-AC13 -> 0
A14: =+'Base_Resultado Mensal_V2'!A85 -> Ocupação | B14: ='DRE 2026'!C10 -> 27197.48 | C14: ='Base_Resultado Mensal_V2'!C85 -> 27660.2 | D14: =+B14-C14 -> -462.72 | E14: =(C14/B14) -> 1.0170133 | F14: ='DRE 2026'!D10 -> 34236.38 | G14: ='Base_Resultado Mensal_V2'!D85 -> 34729.91 | H14: =+F14-G14 -> -493.53 | I14: =(G14/F14) -> 1.0144154 | J14: ='DRE 2026'!E10 -> 34236.38 | K14: ='Base_Resultado Mensal_V2'!E85 -> 36273.05 | L14: =+J14-K14 -> -2036.67 | M14: =(K14/J14) -> 1.0594885 | N14: ='DRE 2026'!F10 -> 34236.38 | O14: ='Base_Resultado Mensal_V2'!F85 -> 36198.98 | P14: =+N14-O14 -> -1962.6 | Q14: =(O14/N14) -> 1.057325 | R14: ='DRE 2026'!G10 -> 34236.38 | S14: ='Base_Resultado Mensal_V2'!G85 -> 37189.87 | T14: =+R14-S14 -> -2953.49 | U14: =(S14/R14) -> 1.0862676 | V14: ='DRE 2026'!B10 -> 410635.68 | W14: ='DRE 2026'!C10+'DRE 2026'!D10+'DRE 2026'!E10+'DRE 2026'!F10+'DRE 2026'!G10 -> 164143 | X14: ='Base_Resultado Mensal_V2'!B85 -> 172052.01 | Y14: =W14-X14 -> -7909.01 | Z14: =X14/W14 -> 1.0481837 | AA14: =V14-X14 -> 238583.67 | AC14: =C14+G14+K14+O14+S14 -> 172052.01 | AD14: =X14-AC14 -> 0
A15: =+'Base_Resultado Mensal_V2'!A92 -> Telecomunicações | B15: ='DRE 2026'!C11 -> 890 | C15: ='Base_Resultado Mensal_V2'!C92 -> 807.16 | D15: =+B15-C15 -> 82.84 | E15: =(C15/B15) -> 0.90692135 | F15: ='DRE 2026'!D11 -> 839.7638 | G15: ='Base_Resultado Mensal_V2'!D92 -> 807.16 | H15: =+F15-G15 -> 32.6038 | I15: =(G15/F15) -> 0.96117504 | J15: ='DRE 2026'!E11 -> 839.7638 | K15: ='Base_Resultado Mensal_V2'!E92 -> 807.16 | L15: =+J15-K15 -> 32.6038 | M15: =(K15/J15) -> 0.96117504 | N15: ='DRE 2026'!F11 -> 839.7638 | O15: ='Base_Resultado Mensal_V2'!F92 -> 824.81 | P15: =+N15-O15 -> 14.9538 | Q15: =(O15/N15) -> 0.98219285 | R15: ='DRE 2026'!G11 -> 839.7638 | S15: ='Base_Resultado Mensal_V2'!G92 -> 825.01 | T15: =+R15-S15 -> 14.7538 | U15: =(S15/R15) -> 0.98243101 | V15: ='DRE 2026'!B11 -> 10127.402 | W15: ='DRE 2026'!C11+'DRE 2026'!D11+'DRE 2026'!E11+'DRE 2026'!F11+'DRE 2026'!G11 -> 4249.0552 | X15: ='Base_Resultado Mensal_V2'!B92 -> 4071.3 | Y15: =W15-X15 -> 177.7552 | Z15: =X15/W15 -> 0.95816595 | AA15: =V15-X15 -> 6056.1018 | AC15: =C15+G15+K15+O15+S15 -> 4071.3 | AD15: =X15-AC15 -> 0
